Workbook

Sheet Centro
A1: Ventas semanales por centro — Canal Minorista (pedidos)
A2: Monto neto sin ITBIS de pedidos (estatus 2/7/11). Semana lunes–domingo; la última (amarilla) es ESTIMADA: días transcurridos reales + promedio del mismo día de las últimas 4 semanas completas.
A3: Corte (clave en Detalle) | B3: Centro
A4: Inicio de semana (lunes) | B4: 46258 | D4: 46265 | F4: 46272 | H4: 46279 | J4: 46286 | L4: 46293 | N4: 46300 | P4: 46307
A5: Centro | B5: Sem 35 (24/08) | C5: vs sem. ant. | D5: Sem 36 (31/08) | E5: vs sem. ant. | F5: Sem 37 (07/09) | G5: vs sem. ant. | H5: Sem 38 (14/09) | I5: vs sem. ant. | J5: Sem 39 (21/09) | K5: vs sem. ant. | L5: Sem 40 (28/09) | M5: vs sem. ant. | N5: Sem 41 (05/10) | O5: vs sem. ant. | P5: Sem 42 (12/10) · EST. | Q5: vs sem. ant.
A6: Centro Azua | B6: =SUMIFS(Detalle!$G:$G,Detalle!$A:$A,$B$3,Detalle!$B:$B,$A6,Detalle!$D:$D,B$4) -> 6045346.1 | C6: =IF(SUMIFS(Detalle!$H:$H,Detalle!$A:$A,$B$3,Detalle!$B:$B,$A6,Detalle!$D:$D,B$4)<=0,IF(B6>0,"▲ nuevo","="),IF(B6>SUMIFS(Detalle!$H:$H,Detalle!$A:$A,$B$3,Detalle!$B:$B,$A6,Detalle!$D:$D,B$4),"▲",IF(B6<SUMIFS(Detalle!$H:$H,Detalle!$A:$A,$B$3,Detalle!$B:$B,$A6,Detalle!$D:$D,B$4),"▼","="))&" "&TEXT((B6-SUMIFS(Detalle!$H:$H,Detalle!$A:$A,$B$3,Detalle!$B:$B,$A6,Detalle!$D:$D,B$4))/SUMIFS(Detalle!$H:$H,Detalle!$A:$A,$B$3,Detalle!$B:$B,$A6,Detalle!$D:$D,B$4),"0.0%")) -> ▼ -2.9% | D6: =SUMIFS(Detalle!$G:$G,Detalle!$A:$A,$B$3,Detalle!$B:$B,$A6,Detalle!$D:$D,D$4) -> 6500363.4 | E6: =IF(SUMIFS(Detalle!$H:$H,Detalle!$A:$A,$B$3,Detalle!$B:$B,$A6,Detalle!$D:$D,D$4)<=0,IF(D6>0,"▲ nuevo","="),IF(D6>SUMIFS(Detalle!$H:$H,Detalle!$A:$A,$B$3,Detalle!$B:$B,$A6,Detalle!$D:$D,D$4),"▲",IF(D6<SUMIFS(Detalle!$H:$H,Detalle!$A:$A,$B$3,Detalle!$B:$B,$A6,Detalle!$D:$D,D$4),"▼","="))&" "&TEXT((D6-SUMIFS(Detalle!$H:$H,Detalle!$A:$A,$B$3,Detalle!$B:$B,$A6,Detalle!$D:$D,D$4))/SUMIFS(Detalle!$H:$H,Detalle!$A:$A,$B$3,Detalle!$B:$B,$A6,Detalle!$D:$D,D$4),"0.0%")) -> ▲ 7.5% | F6: =SUMIFS(Detalle!$G:$G,Detalle!$A:$A,$B$3,Detalle!$B:$B,$A6,Detalle!$D:$D,F$4) -> 7083336.4 | G6: =IF(SUMIFS(Detalle!$H:$H,Detalle!$A:$A,$B$3,Detalle!$B:$B,$A6,Detalle!$D:$D,F$4)<=0,IF(F6>0,"▲ nuevo","="),IF(F6>SUMIFS(Detalle!$H:$H,Detalle!$A:$A,$B$3,Detalle!$B:$B,$A6,Detalle!$D:$D,F$4),"▲",IF(F6<SUMIFS(Detalle!$H:$H,Detalle!$A:$A,$B$3,Detalle!$B:$B,$A6,Detalle!$D:$D,F$4),"▼","="))&" "&TEXT((F6-SUMIFS(Detalle!$H:$H,Detalle!$A:$A,$B$3,Detalle!$B:$B,$A6,Detalle!$D:$D,F$4))/SUMIFS(Detalle!$H:$H,Detalle!$A:$A,$B$3,Detalle!$B:$B,$A6,Detalle!$D:$D,F$4),"0.0%")) -> ▲ 9.0% | H6: =SUMIFS(Detalle!$G:$G,Detalle!$A:$A,$B$3,Detalle!$B:$B,$A6,Detalle!$D:$D,H$4) -> 6238437.3 | I6: =IF(SUMIFS(Detalle!$H:$H,Detalle!$A:$A,$B$3,Detalle!$B:$B,$A6,Detalle!$D:$D,H$4)<=0,IF(H6>0,"▲ nuevo","="),IF(H6>SUMIFS(Detalle!$H:$H,Detalle!$A:$A,$B$3,Detalle!$B:$B,$A6,Detalle!$D:$D,H$4),"▲",IF(H6<SUMIFS(Detalle!$H:$H,Detalle!$A:$A,$B$3,Detalle!$B:$B,$A6,Detalle!$D:$D,H$4),"▼","="))&" "&TEXT((H6-SUMIFS(Detalle!$H:$H,Detalle!$A:$A,$B$3,Detalle!$B:$B,$A6,Detalle!$D:$D,H$4))/SUMIFS(Detalle!$H:$H,Detalle!$A:$A,$B$3,Detalle!$B:$B,$A6,Detalle!$D:$D,H$4),"0.0%")) -> ▼ -11.9% | J6: =SUMIFS(Detalle!$G:$G,Detalle!$A:$A,$B$3,Detalle!$B:$B,$A6,Detalle!$D:$D,J$4) -> 6366560.6 | K6: =IF(SUMIFS(Detalle!$H:$H,Detalle!$A:$A,$B$3,Detalle!$B:$B,$A6,Detalle!$D:$D,J$4)<=0,IF(J6>0,"▲ nuevo","="),IF(J6>SUMIFS(Detalle!$H:$H,Detalle!$A:$A,$B$3,Detalle!$B:$B,$A6,Detalle!$D:$D,J$4),"▲",IF(J6<SUMIFS(Detalle!$H:$H,Detalle!$A:$A,$B$3,Detalle!$B:$B,$A6,Detalle!$D:$D,J$4),"▼","="))&" "&TEXT((J6-SUMIFS(Detalle!$H:$H,Detalle!$A:$A,$B$3,Detalle!$B:$B,$A6,Detalle!$D:$D,J$4))/SUMIFS(Detalle!$H:$H,Detalle!$A:$A,$B$3,Detalle!$B:$B,$A6,Detalle!$D:$D,J$4),"0.0%")) -> ▲ 2.1% | L6: =SUMIFS(Detalle!$G:$G,Detalle!$A:$A,$B$3,Detalle!$B:$B,$A6,Detalle!$D:$D,L$4) -> 5708900.4 | M6: =IF(SUMIFS(Detalle!$H:$H,Detalle!$A:$A,$B$3,Detalle!$B:$B,$A6,Detalle!$D:$D,L$4)<=0,IF(L6>0,"▲ nuevo","="),IF(L6>SUMIFS(Detalle!$H:$H,Detalle!$A:$A,$B$3,Detalle!$B:$B,$A6,Detalle!$D:$D,L$4),"▲",IF(L6<SUMIFS(Detalle!$H:$H,Detalle!$A:$A,$B$3,Detalle!$B:$B,$A6,Detalle!$D:$D,L$4),"▼","="))&" "&TEXT((L6-SUMIFS(Detalle!$H:$H,Detalle!$A:$A,$B$3,Detalle!$B:$B,$A6,Detalle!$D:$D,L$4))/SUMIFS(Detalle!$H:$H,Detalle!$A:$A,$B$3,Detalle!$B:$B,$A6,Detalle!$D:$D,L$4),"0.0%")) -> ▼ -10.3% | N6: =SUMIFS(Detalle!$G:$G,Detalle!$A:$A,$B$3,Detalle!$B:$B,$A6,Detalle!$D:$D,N$4) -> 5732954.4 | O6: =IF(SUMIFS(Detalle!$H:$H,Detalle!$A:$A,$B$3,Detalle!$B:$B,$A6,Detalle!$D:$D,N$4)<=0,IF(N6>0,"▲ nuevo","="),IF(N6>SUMIFS(Detalle!$H:$H,Detalle!$A:$A,$B$3,Detalle!$B:$B,$A6,Detalle!$D:$D,N$4),"▲",IF(N6<SUMIFS(Detalle!$H:$H,Detalle!$A:$A,$B$3,Detalle!$B:$B,$A6,Detalle!$D:$D,N$4),"▼","="))&" "&TEXT((N6-SUMIFS(Detalle!$H:$H,Detalle!$A:$A,$B$3,Detalle!$B:$B,$A6,Detalle!$D:$D,N$4))/SUMIFS(Detalle!$H:$H,Detalle!$A:$A,$B$3,Detalle!$B:$B,$A6,Detalle!$D:$D,N$4),"0.0%")) -> ▲ 0.4% | P6: =SUMIFS(Detalle!$G:$G,Detalle!$A:$A,$B$3,Detalle!$B:$B,$A6,Detalle!$D:$D,P$4) -> 5866011.7 | Q6: =IF(SUMIFS(Detalle!$H:$H,Detalle!$A:$A,$B$3,Detalle!$B:$B,$A6,Detalle!$D:$D,P$4)<=0,IF(P6>0,"▲ nuevo","="),IF(P6>SUMIFS(Detalle!$H:$H,Detalle!$A:$A,$B$3,Detalle!$B:$B,$A6,Detalle!$D:$D,P$4),"▲",IF(P6<SUMIFS(Detalle!$H:$H,Detalle!$A:$A,$B$3,Detalle!$B:$B,$A6,Detalle!$D:$D,P$4),"▼","="))&" "&TEXT((P6-SUMIFS(Detalle!$H:$H,Detalle!$A:$A,$B$3,Detalle!$B:$B,$A6,Detalle!$D:$D,P$4))/SUMIFS(Detalle!$H:$H,Detalle!$A:$A,$B$3,Detalle!$B:$B,$A6,Detalle!$D:$D,P$4),"0.0%")) -> ▲ 2.3%
A7: Centro Santo Domingo | B7: =SUMIFS(Detalle!$G:$G,Detalle!$A:$A,$B$3,Detalle!$B:$B,$A7,Detalle!$D:$D,B$4) -> 5181685.3 | C7: =IF(SUMIFS(Detalle!$H:$H,Detalle!$A:$A,$B$3,Detalle!$B:$B,$A7,Detalle!$D:$D,B$4)<=0,IF(B7>0,"▲ nuevo","="),IF(B7>SUMIFS(Detalle!$H:$H,Detalle!$A:$A,$B$3,Detalle!$B:$B,$A7,Detalle!$D:$D,B$4),"▲",IF(B7<SUMIFS(Detalle!$H:$H,Detalle!$A:$A,$B$3,Detalle!$B:$B,$A7,Detalle!$D:$D,B$4),"▼","="))&" "&TEXT((B7-SUMIFS(Detalle!$H:$H,Detalle!$A:$A,$B$3,Detalle!$B:$B,$A7,Detalle!$D:$D,B$4))/SUMIFS(Detalle!$H:$H,Detalle!$A:$A,$B$3,Detalle!$B:$B,$A7,Detalle!$D:$D,B$4),"0.0%")) -> ▼ -3.9% | D7: =SUMIFS(Detalle!$G:$G,Detalle!$A:$A,$B$3,Detalle!$B:$B,$A7,Detalle!$D:$D,D$4) -> 5420464 | E7: =IF(SUMIFS(Detalle!$H:$H,Detalle!$A:$A,$B$3,Detalle!$B:$B,$A7,Detalle!$D:$D,D$4)<=0,IF(D7>0,"▲ nuevo","="),IF(D7>SUMIFS(Detalle!$H:$H,Detalle!$A:$A,$B$3,Detalle!$B:$B,$A7,Detalle!$D:$D,D$4),"▲",IF(D7<SUMIFS(Detalle!$H:$H,Detalle!$A:$A,$B$3,Detalle!$B:$B,$A7,Detalle!$D:$D,D$4),"▼","="))&" "&TEXT((D7-SUMIFS(Detalle!$H:$H,Detalle!$A:$A,$B$3,Detalle!$B:$B,$A7,Detalle!$D:$D,D$4))/SUMIFS(Detalle!$H:$H,Detalle!$A:$A,$B$3,Detalle!$B:$B,$A7,Detalle!$D:$D,D$4),"0.0%")) -> ▲ 4.6% | F7: =SUMIFS(Detalle!$G:$G,Detalle!$A:$A,$B$3,Detalle!$B:$B,$A7,Detalle!$D:$D,F$4) -> 6145997.2 | G7: =IF(SUMIFS(Detalle!$H:$H,Detalle!$A:$A,$B$3,Detalle!$B:$B,$A7,Detalle!$D:$D,F$4)<=0,IF(F7>0,"▲ nuevo","="),IF(F7>SUMIFS(Detalle!$H:$H,Detalle!$A:$A,$B$3,Detalle!$B:$B,$A7,Detalle!$D:$D,F$4),"▲",IF(F7<SUMIFS(Detalle!$H:$H,Detalle!$A:$A,$B$3,Detalle!$B:$B,$A7,Detalle!$D:$D,F$4),"▼","="))&" "&TEXT((F7-SUMIFS(Detalle!$H:$H,Detalle!$A:$A,$B$3,Detalle!$B:$B,$A7,Detalle!$D:$D,F$4))/SUMIFS(Detalle!$H:$H,Detalle!$A:$A,$B$3,Detalle!$B:$B,$A7,Detalle!$D:$D,F$4),"0.0%")) -> ▲ 13.4% | H7: =SUMIFS(Detalle!$G:$G,Detalle!$A:$A,$B$3,Detalle!$B:$B,$A7,Detalle!$D:$D,H$4) -> 5684983.7 | I7: =IF(SUMIFS(Detalle!$H:$H,Detalle!$A:$A,$B$3,Detalle!$B:$B,$A7,Detalle!$D:$D,H$4)<=0,IF(H7>0,"▲ nuevo","="),IF(H7>SUMIFS(Detalle!$H:$H,Detalle!$A:$A,$B$3,Detalle!$B:$B,$A7,Detalle!$D:$D,H$4),"▲",IF(H7<SUMIFS(Detalle!$H:$H,Detalle!$A:$A,$B$3,Detalle!$B:$B,$A7,Detalle!$D:$D,H$4),"▼","="))&" "&TEXT((H7-SUMIFS(Detalle!$H:$H,Detalle!$A:$A,$B$3,Detalle!$B:$B,$A7,Detalle!$D:$D,H$4))/SUMIFS(Detalle!$H:$H,Detalle!$A:$A,$B$3,Detalle!$B:$B,$A7,Detalle!$D:$D,H$4),"0.0%")) -> ▼ -7.5% | J7: =SUMIFS(Detalle!$G:$G,Detalle!$A:$A,$B$3,Detalle!$B:$B,$A7,Detalle!$D:$D,J$4) -> 5953575 | K7: =IF(SUMIFS(Detalle!$H:$H,Detalle!$A:$A,$B$3,Detalle!$B:$B,$A7,Detalle!$D:$D,J$4)<=0,IF(J7>0,"▲ nuevo","="),IF(J7>SUMIFS(Detalle!$H:$H,Detalle!$A:$A,$B$3,Detalle!$B:$B,$A7,Detalle!$D:$D,J$4),"▲",IF(J7<SUMIFS(Detalle!$H:$H,Detalle!$A:$A,$B$3,Detalle!$B:$B,$A7,Detalle!$D:$D,J$4),"▼","="))&" "&TEXT((J7-SUMIFS(Detalle!$H:$H,Detalle!$A:$A,$B$3,Detalle!$B:$B,$A7,Detalle!$D:$D,J$4))/SUMIFS(Detalle!$H:$H,Detalle!$A:$A,$B$3,Detalle!$B:$B,$A7,Detalle!$D:$D,J$4),"0.0%")) -> ▲ 4.7% | L7: =SUMIFS(Detalle!$G:$G,Detalle!$A:$A,$B$3,Detalle!$B:$B,$A7,Detalle!$D:$D,L$4) -> 5658529.3 | M7: =IF(SUMIFS(Detalle!$H:$H,Detalle!$A:$A,$B$3,Detalle!$B:$B,$A7,Detalle!$D:$D,L$4)<=0,IF(L7>0,"▲ nuevo","="),IF(L7>SUMIFS(Detalle!$H:$H,Detalle!$A:$A,$B$3,Detalle!$B:$B,$A7,Detalle!$D:$D,L$4),"▲",IF(L7<SUMIFS(Detalle!$H:$H,Detalle!$A:$A,$B$3,Detalle!$B:$B,$A7,Detalle!$D:$D,L$4),"▼","="))&" "&TEXT((L7-SUMIFS(Detalle!$H:$H,Detalle!$A:$A,$B$3,Detalle!$B:$B,$A7,Detalle!$D:$D,L$4))/SUMIFS(Detalle!$H:$H,Detalle!$A:$A,$B$3,Detalle!$B:$B,$A7,Detalle!$D:$D,L$4),"0.0%")) -> ▼ -5.0% | N7: =SUMIFS(Detalle!$G:$G,Detalle!$A:$A,$B$3,Detalle!$B:$B,$A7,Detalle!$D:$D,N$4) -> 5557605.9 | O7: =IF(SUMIFS(Detalle!$H:$H,Detalle!$A:$A,$B$3,Detalle!$B:$B,$A7,Detalle!$D:$D,N$4)<=0,IF(N7>0,"▲ nuevo","="),IF(N7>SUMIFS(Detalle!$H:$H,Detalle!$A:$A,$B$3,Detalle!$B:$B,$A7,Detalle!$D:$D,N$4),"▲",IF(N7<SUMIFS(Detalle!$H:$H,Detalle!$A:$A,$B$3,Detalle!$B:$B,$A7,Detalle!$D:$D,N$4),"▼","="))&" "&TEXT((N7-SUMIFS(Detalle!$H:$H,Detalle!$A:$A,$B$3,Detalle!$B:$B,$A7,Detalle!$D:$D,N$4))/SUMIFS(Detalle!$H:$H,Detalle!$A:$A,$B$3,Detalle!$B:$B,$A7,Detalle!$D:$D,N$4),"0.0%")) -> ▼ -1.8% | P7: =SUMIFS(Detalle!$G:$G,Detalle!$A:$A,$B$3,Detalle!$B:$B,$A7,Detalle!$D:$D,P$4) -> 5611001.5 | Q7: =IF(SUMIFS(Detalle!$H:$H,Detalle!$A:$A,$B$3,Detalle!$B:$B,$A7,Detalle!$D:$D,P$4)<=0,IF(P7>0,"▲ nuevo","="),IF(P7>SUMIFS(Detalle!$H:$H,Detalle!$A:$A,$B$3,Detalle!$B:$B,$A7,Detalle!$D:$D,P$4),"▲",IF(P7<SUMIFS(Detalle!$H:$H,Detalle!$A:$A,$B$3,Detalle!$B:$B,$A7,Detalle!$D:$D,P$4),"▼","="))&" "&TEXT((P7-SUMIFS(Detalle!$H:$H,Detalle!$A:$A,$B$3,Detalle!$B:$B,$A7,Detalle!$D:$D,P$4))/SUMIFS(Detalle!$H:$H,Detalle!$A:$A,$B$3,Detalle!$B:$B,$A7,Detalle!$D:$D,P$4),"0.0%")) -> ▲ 1.0%
A8: TOTAL MINORISTA | B8: =SUMIFS(Detalle!$G:$G,Detalle!$A:$A,"Total",Detalle!$B:$B,"Minorista",Detalle!$D:$D,B$4) -> 11227031 | C8: =IF(SUMIFS(Detalle!$H:$H,Detalle!$A:$A,"Total",Detalle!$B:$B,"Minorista",Detalle!$D:$D,B$4)<=0,IF(B8>0,"▲ nuevo","="),IF(B8>SUMIFS(Detalle!$H:$H,Detalle!$A:$A,"Total",Detalle!$B:$B,"Minorista",Detalle!$D:$D,B$4),"▲",IF(B8<SUMIFS(Detalle!$H:$H,Detalle!$A:$A,"Total",Detalle!$B:$B,"Minorista",Detalle!$D:$D,B$4),"▼","="))&" "&TEXT((B8-SUMIFS(Detalle!$H:$H,Detalle!$A:$A,"Total",Detalle!$B:$B,"Minorista",Detalle!$D:$D,B$4))/SUMIFS(Detalle!$H:$H,Detalle!$A:$A,"Total",Detalle!$B:$B,"Minorista",Detalle!$D:$D,B$4),"0.0%")) -> ▼ -3.3% | D8: =SUMIFS(Detalle!$G:$G,Detalle!$A:$A,"Total",Detalle!$B:$B,"Minorista",Detalle!$D:$D,D$4) -> 11920827 | E8: =IF(SUMIFS(Detalle!$H:$H,Detalle!$A:$A,"Total",Detalle!$B:$B,"Minorista",Detalle!$D:$D,D$4)<=0,IF(D8>0,"▲ nuevo","="),IF(D8>SUMIFS(Detalle!$H:$H,Detalle!$A:$A,"Total",Detalle!$B:$B,"Minorista",Detalle!$D:$D,D$4),"▲",IF(D8<SUMIFS(Detalle!$H:$H,Detalle!$A:$A,"Total",Detalle!$B:$B,"Minorista",Detalle!$D:$D,D$4),"▼","="))&" "&TEXT((D8-SUMIFS(Detalle!$H:$H,Detalle!$A:$A,"Total",Detalle!$B:$B,"Minorista",Detalle!$D:$D,D$4))/SUMIFS(Detalle!$H:$H,Detalle!$A:$A,"Total",Detalle!$B:$B,"Minorista",Detalle!$D:$D,D$4),"0.0%")) -> ▲ 6.2% | F8: =SUMIFS(Detalle!$G:$G,Detalle!$A:$A,"Total",Detalle!$B:$B,"Minorista",Detalle!$D:$D,F$4) -> 13229334 | G8: =IF(SUMIFS(Detalle!$H:$H,Detalle!$A:$A,"Total",Detalle!$B:$B,"Minorista",Detalle!$D:$D,F$4)<=0,IF(F8>0,"▲ nuevo","="),IF(F8>SUMIFS(Detalle!$H:$H,Detalle!$A:$A,"Total",Detalle!$B:$B,"Minorista",Detalle!$D:$D,F$4),"▲",IF(F8<SUMIFS(Detalle!$H:$H,Detalle!$A:$A,"Total",Detalle!$B:$B,"Minorista",Detalle!$D:$D,F$4),"▼","="))&" "&TEXT((F8-SUMIFS(Detalle!$H:$H,Detalle!$A:$A,"Total",Detalle!$B:$B,"Minorista",Detalle!$D:$D,F$4))/SUMIFS(Detalle!$H:$H,Detalle!$A:$A,"Total",Detalle!$B:$B,"Minorista",Detalle!$D:$D,F$4),"0.0%")) -> ▲ 11.0% | H8: =SUMIFS(Detalle!$G:$G,Detalle!$A:$A,"Total",Detalle!$B:$B,"Minorista",Detalle!$D:$D,H$4) -> 11923421 | I8: =IF(SUMIFS(Detalle!$H:$H,Detalle!$A:$A,"Total",Detalle!$B:$B,"Minorista",Detalle!$D:$D,H$4)<=0,IF(H8>0,"▲ nuevo","="),IF(H8>SUMIFS(Detalle!$H:$H,Detalle!$A:$A,"Total",Detalle!$B:$B,"Minorista",Detalle!$D:$D,H$4),"▲",IF(H8<SUMIFS(Detalle!$H:$H,Detalle!$A:$A,"Total",Detalle!$B:$B,"Minorista",Detalle!$D:$D,H$4),"▼","="))&" "&TEXT((H8-SUMIFS(Detalle!$H:$H,Detalle!$A:$A,"Total",Detalle!$B:$B,"Minorista",Detalle!$D:$D,H$4))/SUMIFS(Detalle!$H:$H,Detalle!$A:$A,"Total",Detalle!$B:$B,"Minorista",Detalle!$D:$D,H$4),"0.0%")) -> ▼ -9.9% | J8: =SUMIFS(Detalle!$G:$G,Detalle!$A:$A,"Total",Detalle!$B:$B,"Minorista",Detalle!$D:$D,J$4) -> 12320136 | K8: =IF(SUMIFS(Detalle!$H:$H,Detalle!$A:$A,"Total",Detalle!$B:$B,"Minorista",Detalle!$D:$D,J$4)<=0,IF(J8>0,"▲ nuevo","="),IF(J8>SUMIFS(Detalle!$H:$H,Detalle!$A:$A,"Total",Detalle!$B:$B,"Minorista",Detalle!$D:$D,J$4),"▲",IF(J8<SUMIFS(Detalle!$H:$H,Detalle!$A:$A,"Total",Detalle!$B:$B,"Minorista",Detalle!$D:$D,J$4),"▼","="))&" "&TEXT((J8-SUMIFS(Detalle!$H:$H,Detalle!$A:$A,"Total",Detalle!$B:$B,"Minorista",Detalle!$D:$D,J$4))/SUMIFS(Detalle!$H:$H,Detalle!$A:$A,"Total",Detalle!$B:$B,"Minorista",Detalle!$D:$D,J$4),"0.0%")) -> ▲ 3.3% | L8: =SUMIFS(Detalle!$G:$G,Detalle!$A:$A,"Total",Detalle!$B:$B,"Minorista",Detalle!$D:$D,L$4) -> 11367430 | M8: =IF(SUMIFS(Detalle!$H:$H,Detalle!$A:$A,"Total",Detalle!$B:$B,"Minorista",Detalle!$D:$D,L$4)<=0,IF(L8>0,"▲ nuevo","="),IF(L8>SUMIFS(Detalle!$H:$H,Detalle!$A:$A,"Total",Detalle!$B:$B,"Minorista",Detalle!$D:$D,L$4),"▲",IF(L8<SUMIFS(Detalle!$H:$H,Detalle!$A:$A,"Total",Detalle!$B:$B,"Minorista",Detalle!$D:$D,L$4),"▼","="))&" "&TEXT((L8-SUMIFS(Detalle!$H:$H,Detalle!$A:$A,"Total",Detalle!$B:$B,"Minorista",Detalle!$D:$D,L$4))/SUMIFS(Detalle!$H:$H,Detalle!$A:$A,"Total",Detalle!$B:$B,"Minorista",Detalle!$D:$D,L$4),"0.0%")) -> ▼ -7.7% | N8: =SUMIFS(Detalle!$G:$G,Detalle!$A:$A,"Total",Detalle!$B:$B,"Minorista",Detalle!$D:$D,N$4) -> 11290560 | O8: =IF(SUMIFS(Detalle!$H:$H,Detalle!$A:$A,"Total",Detalle!$B:$B,"Minorista",Detalle!$D:$D,N$4)<=0,IF(N8>0,"▲ nuevo","="),IF(N8>SUMIFS(Detalle!$H:$H,Detalle!$A:$A,"Total",Detalle!$B:$B,"Minorista",Detalle!$D:$D,N$4),"▲",IF(N8<SUMIFS(Detalle!$H:$H,Detalle!$A:$A,"Total",Detalle!$B:$B,"Minorista",Detalle!$D:$D,N$4),"▼","="))&" "&TEXT((N8-SUMIFS(Detalle!$H:$H,Detalle!$A:$A,"Total",Detalle!$B:$B,"Minorista",Detalle!$D:$D,N$4))/SUMIFS(Detalle!$H:$H,Detalle!$A:$A,"Total",Detalle!$B:$B,"Minorista",Detalle!$D:$D,N$4),"0.0%")) -> ▼ -0.7% | P8: =SUMIFS(Detalle!$G:$G,Detalle!$A:$A,"Total",Detalle!$B:$B,"Minorista",Detalle!$D:$D,P$4) -> 11477013 | Q8: =IF(SUMIFS(Detalle!$H:$H,Detalle!$A:$A,"Total",Detalle!$B:$B,"Minorista",Detalle!$D:$D,P$4)<=0,IF(P8>0,"▲ nuevo","="),IF(P8>SUMIFS(Detalle!$H:$H,Detalle!$A:$A,"Total",Detalle!$B:$B,"Minorista",Detalle!$D:$D,P$4),"▲",IF(P8<SUMIFS(Detalle!$H:$H,Detalle!$A:$A,"Total",Detalle!$B:$B,"Minorista",Detalle!$D:$D,P$4),"▼","="))&" "&TEXT((P8-SUMIFS(Detalle!$H:$H,Detalle!$A:$A,"Total",Detalle!$B:$B,"Minorista",Detalle!$D:$D,P$4))/SUMIFS(Detalle!$H:$H,Detalle!$A:$A,"Total",Detalle!$B:$B,"Minorista",Detalle!$D:$D,P$4),"0.0%")) -> ▲ 1.7%
A9: Control: suma de filas − total (debe ser 0) | B9: =ROUND(SUM(B6:B7)-B8,0) -> 0 | D9: =ROUND(SUM(D6:D7)-D8,0) -> 0 | F9: =ROUND(SUM(F6:F7)-F8,0) -> 0 | H9: =ROUND(SUM(H6:H7)-H8,0) -> 0 | J9: =ROUND(SUM(J6:J7)-J8,0) -> 0 | L9: =ROUND(SUM(L6:L7)-L8,0) -> 0 | N9: =ROUND(SUM(N6:N7)-N8,0) -> 0 | P9: =ROUND(SUM(P6:P7)-P8,0) -> 0

Sheet Supervisor
A1: Ventas semanales por supervisor — Canal Minorista (pedidos)
A2: Monto neto sin ITBIS de pedidos (estatus 2/7/11). Semana lunes–domingo; la última (amarilla) es ESTIMADA: días transcurridos reales + promedio del mismo día de las últimas 4 semanas completas.
A3: Corte (clave en Detalle) | B3: Supervisor
A4: Inicio de semana (lunes) | B4: 46258 | D4: 46265 | F4: 46272 | H4: 46279 | J4: 46286 | L4: 46293 | N4: 46300 | P4: 46307
A5: Supervisor | B5: Sem 35 (24/08) | C5: vs sem. ant. | D5: Sem 36 (31/08) | E5: vs sem. ant. | F5: Sem 37 (07/09) | G5: vs sem. ant. | H5: Sem 38 (14/09) | I5: vs sem. ant. | J5: Sem 39 (21/09) | K5: vs sem. ant. | L5: Sem 40 (28/09) | M5: vs sem. ant. | N5: Sem 41 (05/10) | O5: vs sem. ant. | P5: Sem 42 (12/10) · EST. | Q5: vs sem. ant.
A6: Narciso Piña Bello (Sur L | B6: =SUMIFS(Detalle!$G:$G,Detalle!$A:$A,$B$3,Detalle!$B:$B,$A6,Detalle!$D:$D,B$4) -> 3233955 | C6: =IF(SUMIFS(Detalle!$H:$H,Detalle!$A:$A,$B$3,Detalle!$B:$B,$A6,Detalle!$D:$D,B$4)<=0,IF(B6>0,"▲ nuevo","="),IF(B6>SUMIFS(Detalle!$H:$H,Detalle!$A:$A,$B$3,Detalle!$B:$B,$A6,Detalle!$D:$D,B$4),"▲",IF(B6<SUMIFS(Detalle!$H:$H,Detalle!$A:$A,$B$3,Detalle!$B:$B,$A6,Detalle!$D:$D,B$4),"▼","="))&" "&TEXT((B6-SUMIFS(Detalle!$H:$H,Detalle!$A:$A,$B$3,Detalle!$B:$B,$A6,Detalle!$D:$D,B$4))/SUMIFS(Detalle!$H:$H,Detalle!$A:$A,$B$3,Detalle!$B:$B,$A6,Detalle!$D:$D,B$4),"0.0%")) -> ▲ 0.9% | D6: =SUMIFS(Detalle!$G:$G,Detalle!$A:$A,$B$3,Detalle!$B:$B,$A6,Detalle!$D:$D,D$4) -> 3477033.5 | E6: =IF(SUMIFS(Detalle!$H:$H,Detalle!$A:$A,$B$3,Detalle!$B:$B,$A6,Detalle!$D:$D,D$4)<=0,IF(D6>0,"▲ nuevo","="),IF(D6>SUMIFS(Detalle!$H:$H,Detalle!$A:$A,$B$3,Detalle!$B:$B,$A6,Detalle!$D:$D,D$4),"▲",IF(D6<SUMIFS(Detalle!$H:$H,Detalle!$A:$A,$B$3,Detalle!$B:$B,$A6,Detalle!$D:$D,D$4),"▼","="))&" "&TEXT((D6-SUMIFS(Detalle!$H:$H,Detalle!$A:$A,$B$3,Detalle!$B:$B,$A6,Detalle!$D:$D,D$4))/SUMIFS(Detalle!$H:$H,Detalle!$A:$A,$B$3,Detalle!$B:$B,$A6,Detalle!$D:$D,D$4),"0.0%")) -> ▲ 7.5% | F6: =SUMIFS(Detalle!$G:$G,Detalle!$A:$A,$B$3,Detalle!$B:$B,$A6,Detalle!$D:$D,F$4) -> 4140482.7 | G6: =IF(SUMIFS(Detalle!$H:$H,Detalle!$A:$A,$B$3,Detalle!$B:$B,$A6,Detalle!$D:$D,F$4)<=0,IF(F6>0,"▲ nuevo","="),IF(F6>SUMIFS(Detalle!$H:$H,Detalle!$A:$A,$B$3,Detalle!$B:$B,$A6,Detalle!$D:$D,F$4),"▲",IF(F6<SUMIFS(Detalle!$H:$H,Detalle!$A:$A,$B$3,Detalle!$B:$B,$A6,Detalle!$D:$D,F$4),"▼","="))&" "&TEXT((F6-SUMIFS(Detalle!$H:$H,Detalle!$A:$A,$B$3,Detalle!$B:$B,$A6,Detalle!$D:$D,F$4))/SUMIFS(Detalle!$H:$H,Detalle!$A:$A,$B$3,Detalle!$B:$B,$A6,Detalle!$D:$D,F$4),"0.0%")) -> ▲ 19.1% | H6: =SUMIFS(Detalle!$G:$G,Detalle!$A:$A,$B$3,Detalle!$B:$B,$A6,Detalle!$D:$D,H$4) -> 3188592.9 | I6: =IF(SUMIFS(Detalle!$H:$H,Detalle!$A:$A,$B$3,Detalle!$B:$B,$A6,Detalle!$D:$D,H$4)<=0,IF(H6>0,"▲ nuevo","="),IF(H6>SUMIFS(Detalle!$H:$H,Detalle!$A:$A,$B$3,Detalle!$B:$B,$A6,Detalle!$D:$D,H$4),"▲",IF(H6<SUMIFS(Detalle!$H:$H,Detalle!$A:$A,$B$3,Detalle!$B:$B,$A6,Detalle!$D:$D,H$4),"▼","="))&" "&TEXT((H6-SUMIFS(Detalle!$H:$H,Detalle!$A:$A,$B$3,Detalle!$B:$B,$A6,Detalle!$D:$D,H$4))/SUMIFS(Detalle!$H:$H,Detalle!$A:$A,$B$3,Detalle!$B:$B,$A6,Detalle!$D:$D,H$4),"0.0%")) -> ▼ -23.0% | J6: =SUMIFS(Detalle!$G:$G,Detalle!$A:$A,$B$3,Detalle!$B:$B,$A6,Detalle!$D:$D,J$4) -> 3408123.8 | K6: =IF(SUMIFS(Detalle!$H:$H,Detalle!$A:$A,$B$3,Detalle!$B:$B,$A6,Detalle!$D:$D,J$4)<=0,IF(J6>0,"▲ nuevo","="),IF(J6>SUMIFS(Detalle!$H:$H,Detalle!$A:$A,$B$3,Detalle!$B:$B,$A6,Detalle!$D:$D,J$4),"▲",IF(J6<SUMIFS(Detalle!$H:$H,Detalle!$A:$A,$B$3,Detalle!$B:$B,$A6,Detalle!$D:$D,J$4),"▼","="))&" "&TEXT((J6-SUMIFS(Detalle!$H:$H,Detalle!$A:$A,$B$3,Detalle!$B:$B,$A6,Detalle!$D:$D,J$4))/SUMIFS(Detalle!$H:$H,Detalle!$A:$A,$B$3,Detalle!$B:$B,$A6,Detalle!$D:$D,J$4),"0.0%")) -> ▲ 6.9% | L6: =SUMIFS(Detalle!$G:$G,Detalle!$A:$A,$B$3,Detalle!$B:$B,$A6,Detalle!$D:$D,L$4) -> 3199580.5 | M6: =IF(SUMIFS(Detalle!$H:$H,Detalle!$A:$A,$B$3,Detalle!$B:$B,$A6,Detalle!$D:$D,L$4)<=0,IF(L6>0,"▲ nuevo","="),IF(L6>SUMIFS(Detalle!$H:$H,Detalle!$A:$A,$B$3,Detalle!$B:$B,$A6,Detalle!$D:$D,L$4),"▲",IF(L6<SUMIFS(Detalle!$H:$H,Detalle!$A:$A,$B$3,Detalle!$B:$B,$A6,Detalle!$D:$D,L$4),"▼","="))&" "&TEXT((L6-SUMIFS(Detalle!$H:$H,Detalle!$A:$A,$B$3,Detalle!$B:$B,$A6,Detalle!$D:$D,L$4))/SUMIFS(Detalle!$H:$H,Detalle!$A:$A,$B$3,Detalle!$B:$B,$A6,Detalle!$D:$D,L$4),"0.0%")) -> ▼ -6.1% | N6: =SUMIFS(Detalle!$G:$G,Detalle!$A:$A,$B$3,Detalle!$B:$B,$A6,Detalle!$D:$D,N$4) -> 3048153 | O6: =IF(SUMIFS(Detalle!$H:$H,Detalle!$A:$A,$B$3,Detalle!$B:$B,$A6,Detalle!$D:$D,N$4)<=0,IF(N6>0,"▲ nuevo","="),IF(N6>SUMIFS(Detalle!$H:$H,Detalle!$A:$A,$B$3,Detalle!$B:$B,$A6,Detalle!$D:$D,N$4),"▲",IF(N6<SUMIFS(Detalle!$H:$H,Detalle!$A:$A,$B$3,Detalle!$B:$B,$A6,Detalle!$D:$D,N$4),"▼","="))&" "&TEXT((N6-SUMIFS(Detalle!$H:$H,Detalle!$A:$A,$B$3,Detalle!$B:$B,$A6,Detalle!$D:$D,N$4))/SUMIFS(Detalle!$H:$H,Detalle!$A:$A,$B$3,Detalle!$B:$B,$A6,Detalle!$D:$D,N$4),"0.0%")) -> ▼ -4.7% | P6: =SUMIFS(Detalle!$G:$G,Detalle!$A:$A,$B$3,Detalle!$B:$B,$A6,Detalle!$D:$D,P$4) -> 3142549 | Q6: =IF(SUMIFS(Detalle!$H:$H,Detalle!$A:$A,$B$3,Detalle!$B:$B,$A6,Detalle!$D:$D,P$4)<=0,IF(P6>0,"▲ nuevo","="),IF(P6>SUMIFS(Detalle!$H:$H,Detalle!$A:$A,$B$3,Detalle!$B:$B,$A6,Detalle!$D:$D,P$4),"▲",IF(P6<SUMIFS(Detalle!$H:$H,Detalle!$A:$A,$B$3,Detalle!$B:$B,$A6,Detalle!$D:$D,P$4),"▼","="))&" "&TEXT((P6-SUMIFS(Detalle!$H:$H,Detalle!$A:$A,$B$3,Detalle!$B:$B,$A6,Detalle!$D:$D,P$4))/SUMIFS(Detalle!$H:$H,Detalle!$A:$A,$B$3,Detalle!$B:$B,$A6,Detalle!$D:$D,P$4),"0.0%")) -> ▲ 3.1%
A7: Rafael Otaño Sur Corto (S | B7: =SUMIFS(Detalle!$G:$G,Detalle!$A:$A,$B$3,Detalle!$B:$B,$A7,Detalle!$D:$D,B$4) -> 2811391.2 | C7: =IF(SUMIFS(Detalle!$H:$H,Detalle!$A:$A,$B$3,Detalle!$B:$B,$A7,Detalle!$D:$D,B$4)<=0,IF(B7>0,"▲ nuevo","="),IF(B7>SUMIFS(Detalle!$H:$H,Detalle!$A:$A,$B$3,Detalle!$B:$B,$A7,Detalle!$D:$D,B$4),"▲",IF(B7<SUMIFS(Detalle!$H:$H,Detalle!$A:$A,$B$3,Detalle!$B:$B,$A7,Detalle!$D:$D,B$4),"▼","="))&" "&TEXT((B7-SUMIFS(Detalle!$H:$H,Detalle!$A:$A,$B$3,Detalle!$B:$B,$A7,Detalle!$D:$D,B$4))/SUMIFS(Detalle!$H:$H,Detalle!$A:$A,$B$3,Detalle!$B:$B,$A7,Detalle!$D:$D,B$4),"0.0%")) -> ▼ -6.9% | D7: =SUMIFS(Detalle!$G:$G,Detalle!$A:$A,$B$3,Detalle!$B:$B,$A7,Detalle!$D:$D,D$4) -> 3023329.9 | E7: =IF(SUMIFS(Detalle!$H:$H,Detalle!$A:$A,$B$3,Detalle!$B:$B,$A7,Detalle!$D:$D,D$4)<=0,IF(D7>0,"▲ nuevo","="),IF(D7>SUMIFS(Detalle!$H:$H,Detalle!$A:$A,$B$3,Detalle!$B:$B,$A7,Detalle!$D:$D,D$4),"▲",IF(D7<SUMIFS(Detalle!$H:$H,Detalle!$A:$A,$B$3,Detalle!$B:$B,$A7,Detalle!$D:$D,D$4),"▼","="))&" "&TEXT((D7-SUMIFS(Detalle!$H:$H,Detalle!$A:$A,$B$3,Detalle!$B:$B,$A7,Detalle!$D:$D,D$4))/SUMIFS(Detalle!$H:$H,Detalle!$A:$A,$B$3,Detalle!$B:$B,$A7,Detalle!$D:$D,D$4),"0.0%")) -> ▲ 7.5% | F7: =SUMIFS(Detalle!$G:$G,Detalle!$A:$A,$B$3,Detalle!$B:$B,$A7,Detalle!$D:$D,F$4) -> 2942853.7 | G7: =IF(SUMIFS(Detalle!$H:$H,Detalle!$A:$A,$B$3,Detalle!$B:$B,$A7,Detalle!$D:$D,F$4)<=0,IF(F7>0,"▲ nuevo","="),IF(F7>SUMIFS(Detalle!$H:$H,Detalle!$A:$A,$B$3,Detalle!$B:$B,$A7,Detalle!$D:$D,F$4),"▲",IF(F7<SUMIFS(Detalle!$H:$H,Detalle!$A:$A,$B$3,Detalle!$B:$B,$A7,Detalle!$D:$D,F$4),"▼","="))&" "&TEXT((F7-SUMIFS(Detalle!$H:$H,Detalle!$A:$A,$B$3,Detalle!$B:$B,$A7,Detalle!$D:$D,F$4))/SUMIFS(Detalle!$H:$H,Detalle!$A:$A,$B$3,Detalle!$B:$B,$A7,Detalle!$D:$D,F$4),"0.0%")) -> ▼ -2.7% | H7: =SUMIFS(Detalle!$G:$G,Detalle!$A:$A,$B$3,Detalle!$B:$B,$A7,Detalle!$D:$D,H$4) -> 3049844.4 | I7: =IF(SUMIFS(Detalle!$H:$H,Detalle!$A:$A,$B$3,Detalle!$B:$B,$A7,Detalle!$D:$D,H$4)<=0,IF(H7>0,"▲ nuevo","="),IF(H7>SUMIFS(Detalle!$H:$H,Detalle!$A:$A,$B$3,Detalle!$B:$B,$A7,Detalle!$D:$D,H$4),"▲",IF(H7<SUMIFS(Detalle!$H:$H,Detalle!$A:$A,$B$3,Detalle!$B:$B,$A7,Detalle!$D:$D,H$4),"▼","="))&" "&TEXT((H7-SUMIFS(Detalle!$H:$H,Detalle!$A:$A,$B$3,Detalle!$B:$B,$A7,Detalle!$D:$D,H$4))/SUMIFS(Detalle!$H:$H,Detalle!$A:$A,$B$3,Detalle!$B:$B,$A7,Detalle!$D:$D,H$4),"0.0%")) -> ▲ 3.6% | J7: =SUMIFS(Detalle!$G:$G,Detalle!$A:$A,$B$3,Detalle!$B:$B,$A7,Detalle!$D:$D,J$4) -> 2958436.8 | K7: =IF(SUMIFS(Detalle!$H:$H,Detalle!$A:$A,$B$3,Detalle!$B:$B,$A7,Detalle!$D:$D,J$4)<=0,IF(J7>0,"▲ nuevo","="),IF(J7>SUMIFS(Detalle!$H:$H,Detalle!$A:$A,$B$3,Detalle!$B:$B,$A7,Detalle!$D:$D,J$4),"▲",IF(J7<SUMIFS(Detalle!$H:$H,Detalle!$A:$A,$B$3,Detalle!$B:$B,$A7,Detalle!$D:$D,J$4),"▼","="))&" "&TEXT((J7-SUMIFS(Detalle!$H:$H,Detalle!$A:$A,$B$3,Detalle!$B:$B,$A7,Detalle!$D:$D,J$4))/SUMIFS(Detalle!$H:$H,Detalle!$A:$A,$B$3,Detalle!$B:$B,$A7,Detalle!$D:$D,J$4),"0.0%")) -> ▼ -3.0% | L7: =SUMIFS(Detalle!$G:$G,Detalle!$A:$A,$B$3,Detalle!$B:$B,$A7,Detalle!$D:$D,L$4) -> 2509319.9 | M7: =IF(SUMIFS(Detalle!$H:$H,Detalle!$A:$A,$B$3,Detalle!$B:$B,$A7,Detalle!$D:$D,L$4)<=0,IF(L7>0,"▲ nuevo","="),IF(L7>SUMIFS(Detalle!$H:$H,Detalle!$A:$A,$B$3,Detalle!$B:$B,$A7,Detalle!$D:$D,L$4),"▲",IF(L7<SUMIFS(Detalle!$H:$H,Detalle!$A:$A,$B$3,Detalle!$B:$B,$A7,Detalle!$D:$D,L$4),"▼","="))&" "&TEXT((L7-SUMIFS(Detalle!$H:$H,Detalle!$A:$A,$B$3,Detalle!$B:$B,$A7,Detalle!$D:$D,L$4))/SUMIFS(Detalle!$H:$H,Detalle!$A:$A,$B$3,Detalle!$B:$B,$A7,Detalle!$D:$D,L$4),"0.0%")) -> ▼ -15.2% | N7: =SUMIFS(Detalle!$G:$G,Detalle!$A:$A,$B$3,Detalle!$B:$B,$A7,Detalle!$D:$D,N$4) -> 2684801.4 | O7: =IF(SUMIFS(Detalle!$H:$H,Detalle!$A:$A,$B$3,Detalle!$B:$B,$A7,Detalle!$D:$D,N$4)<=0,IF(N7>0,"▲ nuevo","="),IF(N7>SUMIFS(Detalle!$H:$H,Detalle!$A:$A,$B$3,Detalle!$B:$B,$A7,Detalle!$D:$D,N$4),"▲",IF(N7<SUMIFS(Detalle!$H:$H,Detalle!$A:$A,$B$3,Detalle!$B:$B,$A7,Detalle!$D:$D,N$4),"▼","="))&" "&TEXT((N7-SUMIFS(Detalle!$H:$H,Detalle!$A:$A,$B$3,Detalle!$B:$B,$A7,Detalle!$D:$D,N$4))/SUMIFS(Detalle!$H:$H,Detalle!$A:$A,$B$3,Detalle!$B:$B,$A7,Detalle!$D:$D,N$4),"0.0%")) -> ▲ 7.0% | P7: =SUMIFS(Detalle!$G:$G,Detalle!$A:$A,$B$3,Detalle!$B:$B,$A7,Detalle!$D:$D,P$4) -> 2723462.6 | Q7: =IF(SUMIFS(Detalle!$H:$H,Detalle!$A:$A,$B$3,Detalle!$B:$B,$A7,Detalle!$D:$D,P$4)<=0,IF(P7>0,"▲ nuevo","="),IF(P7>SUMIFS(Detalle!$H:$H,Detalle!$A:$A,$B$3,Detalle!$B:$B,$A7,Detalle!$D:$D,P$4),"▲",IF(P7<SUMIFS(Detalle!$H:$H,Detalle!$A:$A,$B$3,Detalle!$B:$B,$A7,Detalle!$D:$D,P$4),"▼","="))&" "&TEXT((P7-SUMIFS(Detalle!$H:$H,Detalle!$A:$A,$B$3,Detalle!$B:$B,$A7,Detalle!$D:$D,P$4))/SUMIFS(Detalle!$H:$H,Detalle!$A:$A,$B$3,Detalle!$B:$B,$A7,Detalle!$D:$D,P$4),"0.0%")) -> ▲ 1.4%
A8: Ramon E. Pimentel (SDE) | B8: =SUMIFS(Detalle!$G:$G,Detalle!$A:$A,$B$3,Detalle!$B:$B,$A8,Detalle!$D:$D,B$4) -> 1872870.8 | C8: =IF(SUMIFS(Detalle!$H:$H,Detalle!$A:$A,$B$3,Detalle!$B:$B,$A8,Detalle!$D:$D,B$4)<=0,IF(B8>0,"▲ nuevo","="),IF(B8>SUMIFS(Detalle!$H:$H,Detalle!$A:$A,$B$3,Detalle!$B:$B,$A8,Detalle!$D:$D,B$4),"▲",IF(B8<SUMIFS(Detalle!$H:$H,Detalle!$A:$A,$B$3,Detalle!$B:$B,$A8,Detalle!$D:$D,B$4),"▼","="))&" "&TEXT((B8-SUMIFS(Detalle!$H:$H,Detalle!$A:$A,$B$3,Detalle!$B:$B,$A8,Detalle!$D:$D,B$4))/SUMIFS(Detalle!$H:$H,Detalle!$A:$A,$B$3,Detalle!$B:$B,$A8,Detalle!$D:$D,B$4),"0.0%")) -> ▼ -5.2% | D8: =SUMIFS(Detalle!$G:$G,Detalle!$A:$A,$B$3,Detalle!$B:$B,$A8,Detalle!$D:$D,D$4) -> 2122344.4 | E8: =IF(SUMIFS(Detalle!$H:$H,Detalle!$A:$A,$B$3,Detalle!$B:$B,$A8,Detalle!$D:$D,D$4)<=0,IF(D8>0,"▲ nuevo","="),IF(D8>SUMIFS(Detalle!$H:$H,Detalle!$A:$A,$B$3,Detalle!$B:$B,$A8,Detalle!$D:$D,D$4),"▲",IF(D8<SUMIFS(Detalle!$H:$H,Detalle!$A:$A,$B$3,Detalle!$B:$B,$A8,Detalle!$D:$D,D$4),"▼","="))&" "&TEXT((D8-SUMIFS(Detalle!$H:$H,Detalle!$A:$A,$B$3,Detalle!$B:$B,$A8,Detalle!$D:$D,D$4))/SUMIFS(Detalle!$H:$H,Detalle!$A:$A,$B$3,Detalle!$B:$B,$A8,Detalle!$D:$D,D$4),"0.0%")) -> ▲ 13.3% | F8: =SUMIFS(Detalle!$G:$G,Detalle!$A:$A,$B$3,Detalle!$B:$B,$A8,Detalle!$D:$D,F$4) -> 2234177.6 | G8: =IF(SUMIFS(Detalle!$H:$H,Detalle!$A:$A,$B$3,Detalle!$B:$B,$A8,Detalle!$D:$D,F$4)<=0,IF(F8>0,"▲ nuevo","="),IF(F8>SUMIFS(Detalle!$H:$H,Detalle!$A:$A,$B$3,Detalle!$B:$B,$A8,Detalle!$D:$D,F$4),"▲",IF(F8<SUMIFS(Detalle!$H:$H,Detalle!$A:$A,$B$3,Detalle!$B:$B,$A8,Detalle!$D:$D,F$4),"▼","="))&" "&TEXT((F8-SUMIFS(Detalle!$H:$H,Detalle!$A:$A,$B$3,Detalle!$B:$B,$A8,Detalle!$D:$D,F$4))/SUMIFS(Detalle!$H:$H,Detalle!$A:$A,$B$3,Detalle!$B:$B,$A8,Detalle!$D:$D,F$4),"0.0%")) -> ▲ 5.3% | H8: =SUMIFS(Detalle!$G:$G,Detalle!$A:$A,$B$3,Detalle!$B:$B,$A8,Detalle!$D:$D,H$4) -> 2145553.7 | I8: =IF(SUMIFS(Detalle!$H:$H,Detalle!$A:$A,$B$3,Detalle!$B:$B,$A8,Detalle!$D:$D,H$4)<=0,IF(H8>0,"▲ nuevo","="),IF(H8>SUMIFS(Detalle!$H:$H,Detalle!$A:$A,$B$3,Detalle!$B:$B,$A8,Detalle!$D:$D,H$4),"▲",IF(H8<SUMIFS(Detalle!$H:$H,Detalle!$A:$A,$B$3,Detalle!$B:$B,$A8,Detalle!$D:$D,H$4),"▼","="))&" "&TEXT((H8-SUMIFS(Detalle!$H:$H,Detalle!$A:$A,$B$3,Detalle!$B:$B,$A8,Detalle!$D:$D,H$4))/SUMIFS(Detalle!$H:$H,Detalle!$A:$A,$B$3,Detalle!$B:$B,$A8,Detalle!$D:$D,H$4),"0.0%")) -> ▼ -4.0% | J8: =SUMIFS(Detalle!$G:$G,Detalle!$A:$A,$B$3,Detalle!$B:$B,$A8,Detalle!$D:$D,J$4) -> 2180763.5 | K8: =IF(SUMIFS(Detalle!$H:$H,Detalle!$A:$A,$B$3,Detalle!$B:$B,$A8,Detalle!$D:$D,J$4)<=0,IF(J8>0,"▲ nuevo","="),IF(J8>SUMIFS(Detalle!$H:$H,Detalle!$A:$A,$B$3,Detalle!$B:$B,$A8,Detalle!$D:$D,J$4),"▲",IF(J8<SUMIFS(Detalle!$H:$H,Detalle!$A:$A,$B$3,Detalle!$B:$B,$A8,Detalle!$D:$D,J$4),"▼","="))&" "&TEXT((J8-SUMIFS(Detalle!$H:$H,Detalle!$A:$A,$B$3,Detalle!$B:$B,$A8,Detalle!$D:$D,J$4))/SUMIFS(Detalle!$H:$H,Detalle!$A:$A,$B$3,Detalle!$B:$B,$A8,Detalle!$D:$D,J$4),"0.0%")) -> ▲ 1.6% | L8: =SUMIFS(Detalle!$G:$G,Detalle!$A:$A,$B$3,Detalle!$B:$B,$A8,Detalle!$D:$D,L$4) -> 2048327.5 | M8: =IF(SUMIFS(Detalle!$H:$H,Detalle!$A:$A,$B$3,Detalle!$B:$B,$A8,Detalle!$D:$D,L$4)<=0,IF(L8>0,"▲ nuevo","="),IF(L8>SUMIFS(Detalle!$H:$H,Detalle!$A:$A,$B$3,Detalle!$B:$B,$A8,Detalle!$D:$D,L$4),"▲",IF(L8<SUMIFS(Detalle!$H:$H,Detalle!$A:$A,$B$3,Detalle!$B:$B,$A8,Detalle!$D:$D,L$4),"▼","="))&" "&TEXT((L8-SUMIFS(Detalle!$H:$H,Detalle!$A:$A,$B$3,Detalle!$B:$B,$A8,Detalle!$D:$D,L$4))/SUMIFS(Detalle!$H:$H,Detalle!$A:$A,$B$3,Detalle!$B:$B,$A8,Detalle!$D:$D,L$4),"0.0%")) -> ▼ -6.1% | N8: =SUMIFS(Detalle!$G:$G,Detalle!$A:$A,$B$3,Detalle!$B:$B,$A8,Detalle!$D:$D,N$4) -> 2077098.2 | O8: =IF(SUMIFS(Detalle!$H:$H,Detalle!$A:$A,$B$3,Detalle!$B:$B,$A8,Detalle!$D:$D,N$4)<=0,IF(N8>0,"▲ nuevo","="),IF(N8>SUMIFS(Detalle!$H:$H,Detalle!$A:$A,$B$3,Detalle!$B:$B,$A8,Detalle!$D:$D,N$4),"▲",IF(N8<SUMIFS(Detalle!$H:$H,Detalle!$A:$A,$B$3,Detalle!$B:$B,$A8,Detalle!$D:$D,N$4),"▼","="))&" "&TEXT((N8-SUMIFS(Detalle!$H:$H,Detalle!$A:$A,$B$3,Detalle!$B:$B,$A8,Detalle!$D:$D,N$4))/SUMIFS(Detalle!$H:$H,Detalle!$A:$A,$B$3,Detalle!$B:$B,$A8,Detalle!$D:$D,N$4),"0.0%")) -> ▲ 1.4% | P8: =SUMIFS(Detalle!$G:$G,Detalle!$A:$A,$B$3,Detalle!$B:$B,$A8,Detalle!$D:$D,P$4) -> 2048504.8 | Q8: =IF(SUMIFS(Detalle!$H:$H,Detalle!$A:$A,$B$3,Detalle!$B:$B,$A8,Detalle!$D:$D,P$4)<=0,IF(P8>0,"▲ nuevo","="),IF(P8>SUMIFS(Detalle!$H:$H,Detalle!$A:$A,$B$3,Detalle!$B:$B,$A8,Detalle!$D:$D,P$4),"▲",IF(P8<SUMIFS(Detalle!$H:$H,Detalle!$A:$A,$B$3,Detalle!$B:$B,$A8,Detalle!$D:$D,P$4),"▼","="))&" "&TEXT((P8-SUMIFS(Detalle!$H:$H,Detalle!$A:$A,$B$3,Detalle!$B:$B,$A8,Detalle!$D:$D,P$4))/SUMIFS(Detalle!$H:$H,Detalle!$A:$A,$B$3,Detalle!$B:$B,$A8,Detalle!$D:$D,P$4),"0.0%")) -> ▼ -1.4%
A9: Ramon E. Pimentel (SDN) | B9: =SUMIFS(Detalle!$G:$G,Detalle!$A:$A,$B$3,Detalle!$B:$B,$A9,Detalle!$D:$D,B$4) -> 1298175.3 | C9: =IF(SUMIFS(Detalle!$H:$H,Detalle!$A:$A,$B$3,Detalle!$B:$B,$A9,Detalle!$D:$D,B$4)<=0,IF(B9>0,"▲ nuevo","="),IF(B9>SUMIFS(Detalle!$H:$H,Detalle!$A:$A,$B$3,Detalle!$B:$B,$A9,Detalle!$D:$D,B$4),"▲",IF(B9<SUMIFS(Detalle!$H:$H,Detalle!$A:$A,$B$3,Detalle!$B:$B,$A9,Detalle!$D:$D,B$4),"▼","="))&" "&TEXT((B9-SUMIFS(Detalle!$H:$H,Detalle!$A:$A,$B$3,Detalle!$B:$B,$A9,Detalle!$D:$D,B$4))/SUMIFS(Detalle!$H:$H,Detalle!$A:$A,$B$3,Detalle!$B:$B,$A9,Detalle!$D:$D,B$4),"0.0%")) -> ▲ 0.5% | D9: =SUMIFS(Detalle!$G:$G,Detalle!$A:$A,$B$3,Detalle!$B:$B,$A9,Detalle!$D:$D,D$4) -> 1188190.5 | E9: =IF(SUMIFS(Detalle!$H:$H,Detalle!$A:$A,$B$3,Detalle!$B:$B,$A9,Detalle!$D:$D,D$4)<=0,IF(D9>0,"▲ nuevo","="),IF(D9>SUMIFS(Detalle!$H:$H,Detalle!$A:$A,$B$3,Detalle!$B:$B,$A9,Detalle!$D:$D,D$4),"▲",IF(D9<SUMIFS(Detalle!$H:$H,Detalle!$A:$A,$B$3,Detalle!$B:$B,$A9,Detalle!$D:$D,D$4),"▼","="))&" "&TEXT((D9-SUMIFS(Detalle!$H:$H,Detalle!$A:$A,$B$3,Detalle!$B:$B,$A9,Detalle!$D:$D,D$4))/SUMIFS(Detalle!$H:$H,Detalle!$A:$A,$B$3,Detalle!$B:$B,$A9,Detalle!$D:$D,D$4),"0.0%")) -> ▼ -8.5% | F9: =SUMIFS(Detalle!$G:$G,Detalle!$A:$A,$B$3,Detalle!$B:$B,$A9,Detalle!$D:$D,F$4) -> 1516934.9 | G9: =IF(SUMIFS(Detalle!$H:$H,Detalle!$A:$A,$B$3,Detalle!$B:$B,$A9,Detalle!$D:$D,F$4)<=0,IF(F9>0,"▲ nuevo","="),IF(F9>SUMIFS(Detalle!$H:$H,Detalle!$A:$A,$B$3,Detalle!$B:$B,$A9,Detalle!$D:$D,F$4),"▲",IF(F9<SUMIFS(Detalle!$H:$H,Detalle!$A:$A,$B$3,Detalle!$B:$B,$A9,Detalle!$D:$D,F$4),"▼","="))&" "&TEXT((F9-SUMIFS(Detalle!$H:$H,Detalle!$A:$A,$B$3,Detalle!$B:$B,$A9,Detalle!$D:$D,F$4))/SUMIFS(Detalle!$H:$H,Detalle!$A:$A,$B$3,Detalle!$B:$B,$A9,Detalle!$D:$D,F$4),"0.0%")) -> ▲ 27.7% | H9: =SUMIFS(Detalle!$G:$G,Detalle!$A:$A,$B$3,Detalle!$B:$B,$A9,Detalle!$D:$D,H$4) -> 1330074.8 | I9: =IF(SUMIFS(Detalle!$H:$H,Detalle!$A:$A,$B$3,Detalle!$B:$B,$A9,Detalle!$D:$D,H$4)<=0,IF(H9>0,"▲ nuevo","="),IF(H9>SUMIFS(Detalle!$H:$H,Detalle!$A:$A,$B$3,Detalle!$B:$B,$A9,Detalle!$D:$D,H$4),"▲",IF(H9<SUMIFS(Detalle!$H:$H,Detalle!$A:$A,$B$3,Detalle!$B:$B,$A9,Detalle!$D:$D,H$4),"▼","="))&" "&TEXT((H9-SUMIFS(Detalle!$H:$H,Detalle!$A:$A,$B$3,Detalle!$B:$B,$A9,Detalle!$D:$D,H$4))/SUMIFS(Detalle!$H:$H,Detalle!$A:$A,$B$3,Detalle!$B:$B,$A9,Detalle!$D:$D,H$4),"0.0%")) -> ▼ -12.3% | J9: =SUMIFS(Detalle!$G:$G,Detalle!$A:$A,$B$3,Detalle!$B:$B,$A9,Detalle!$D:$D,J$4) -> 1488331 | K9: =IF(SUMIFS(Detalle!$H:$H,Detalle!$A:$A,$B$3,Detalle!$B:$B,$A9,Detalle!$D:$D,J$4)<=0,IF(J9>0,"▲ nuevo","="),IF(J9>SUMIFS(Detalle!$H:$H,Detalle!$A:$A,$B$3,Detalle!$B:$B,$A9,Detalle!$D:$D,J$4),"▲",IF(J9<SUMIFS(Detalle!$H:$H,Detalle!$A:$A,$B$3,Detalle!$B:$B,$A9,Detalle!$D:$D,J$4),"▼","="))&" "&TEXT((J9-SUMIFS(Detalle!$H:$H,Detalle!$A:$A,$B$3,Detalle!$B:$B,$A9,Detalle!$D:$D,J$4))/SUMIFS(Detalle!$H:$H,Detalle!$A:$A,$B$3,Detalle!$B:$B,$A9,Detalle!$D:$D,J$4),"0.0%")) -> ▲ 11.9% | L9: =SUMIFS(Detalle!$G:$G,Detalle!$A:$A,$B$3,Detalle!$B:$B,$A9,Detalle!$D:$D,L$4) -> 1463815.5 | M9: =IF(SUMIFS(Detalle!$H:$H,Detalle!$A:$A,$B$3,Detalle!$B:$B,$A9,Detalle!$D:$D,L$4)<=0,IF(L9>0,"▲ nuevo","="),IF(L9>SUMIFS(Detalle!$H:$H,Detalle!$A:$A,$B$3,Detalle!$B:$B,$A9,Detalle!$D:$D,L$4),"▲",IF(L9<SUMIFS(Detalle!$H:$H,Detalle!$A:$A,$B$3,Detalle!$B:$B,$A9,Detalle!$D:$D,L$4),"▼","="))&" "&TEXT((L9-SUMIFS(Detalle!$H:$H,Detalle!$A:$A,$B$3,Detalle!$B:$B,$A9,Detalle!$D:$D,L$4))/SUMIFS(Detalle!$H:$H,Detalle!$A:$A,$B$3,Detalle!$B:$B,$A9,Detalle!$D:$D,L$4),"0.0%")) -> ▼ -1.6% | N9: =SUMIFS(Detalle!$G:$G,Detalle!$A:$A,$B$3,Detalle!$B:$B,$A9,Detalle!$D:$D,N$4) -> 1247876.4 | O9: =IF(SUMIFS(Detalle!$H:$H,Detalle!$A:$A,$B$3,Detalle!$B:$B,$A9,Detalle!$D:$D,N$4)<=0,IF(N9>0,"▲ nuevo","="),IF(N9>SUMIFS(Detalle!$H:$H,Detalle!$A:$A,$B$3,Detalle!$B:$B,$A9,Detalle!$D:$D,N$4),"▲",IF(N9<SUMIFS(Detalle!$H:$H,Detalle!$A:$A,$B$3,Detalle!$B:$B,$A9,Detalle!$D:$D,N$4),"▼","="))&" "&TEXT((N9-SUMIFS(Detalle!$H:$H,Detalle!$A:$A,$B$3,Detalle!$B:$B,$A9,Detalle!$D:$D,N$4))/SUMIFS(Detalle!$H:$H,Detalle!$A:$A,$B$3,Detalle!$B:$B,$A9,Detalle!$D:$D,N$4),"0.0%")) -> ▼ -14.8% | P9: =SUMIFS(Detalle!$G:$G,Detalle!$A:$A,$B$3,Detalle!$B:$B,$A9,Detalle!$D:$D,P$4) -> 1308213.3 | Q9: =IF(SUMIFS(Detalle!$H:$H,Detalle!$A:$A,$B$3,Detalle!$B:$B,$A9,Detalle!$D:$D,P$4)<=0,IF(P9>0,"▲ nuevo","="),IF(P9>SUMIFS(Detalle!$H:$H,Detalle!$A:$A,$B$3,Detalle!$B:$B,$A9,Detalle!$D:$D,P$4),"▲",IF(P9<SUMIFS(Detalle!$H:$H,Detalle!$A:$A,$B$3,Detalle!$B:$B,$A9,Detalle!$D:$D,P$4),"▼","="))&" "&TEXT((P9-SUMIFS(Detalle!$H:$H,Detalle!$A:$A,$B$3,Detalle!$B:$B,$A9,Detalle!$D:$D,P$4))/SUMIFS(Detalle!$H:$H,Detalle!$A:$A,$B$3,Detalle!$B:$B,$A9,Detalle!$D:$D,P$4),"0.0%")) -> ▲ 4.8%
A10: Eliezer Martinez (SDO) | B10: =SUMIFS(Detalle!$G:$G,Detalle!$A:$A,$B$3,Detalle!$B:$B,$A10,Detalle!$D:$D,B$4) -> 1008709.6 | C10: =IF(SUMIFS(Detalle!$H:$H,Detalle!$A:$A,$B$3,Detalle!$B:$B,$A10,Detalle!$D:$D,B$4)<=0,IF(B10>0,"▲ nuevo","="),IF(B10>SUMIFS(Detalle!$H:$H,Detalle!$A:$A,$B$3,Detalle!$B:$B,$A10,Detalle!$D:$D,B$4),"▲",IF(B10<SUMIFS(Detalle!$H:$H,Detalle!$A:$A,$B$3,Detalle!$B:$B,$A10,Detalle!$D:$D,B$4),"▼","="))&" "&TEXT((B10-SUMIFS(Detalle!$H:$H,Detalle!$A:$A,$B$3,Detalle!$B:$B,$A10,Detalle!$D:$D,B$4))/SUMIFS(Detalle!$H:$H,Detalle!$A:$A,$B$3,Detalle!$B:$B,$A10,Detalle!$D:$D,B$4),"0.0%")) -> ▼ -2.6% | D10: =SUMIFS(Detalle!$G:$G,Detalle!$A:$A,$B$3,Detalle!$B:$B,$A10,Detalle!$D:$D,D$4) -> 977627.2 | E10: =IF(SUMIFS(Detalle!$H:$H,Detalle!$A:$A,$B$3,Detalle!$B:$B,$A10,Detalle!$D:$D,D$4)<=0,IF(D10>0,"▲ nuevo","="),IF(D10>SUMIFS(Detalle!$H:$H,Detalle!$A:$A,$B$3,Detalle!$B:$B,$A10,Detalle!$D:$D,D$4),"▲",IF(D10<SUMIFS(Detalle!$H:$H,Detalle!$A:$A,$B$3,Detalle!$B:$B,$A10,Detalle!$D:$D,D$4),"▼","="))&" "&TEXT((D10-SUMIFS(Detalle!$H:$H,Detalle!$A:$A,$B$3,Detalle!$B:$B,$A10,Detalle!$D:$D,D$4))/SUMIFS(Detalle!$H:$H,Detalle!$A:$A,$B$3,Detalle!$B:$B,$A10,Detalle!$D:$D,D$4),"0.0%")) -> ▼ -3.1% | F10: =SUMIFS(Detalle!$G:$G,Detalle!$A:$A,$B$3,Detalle!$B:$B,$A10,Detalle!$D:$D,F$4) -> 1181904.7 | G10: =IF(SUMIFS(Detalle!$H:$H,Detalle!$A:$A,$B$3,Detalle!$B:$B,$A10,Detalle!$D:$D,F$4)<=0,IF(F10>0,"▲ nuevo","="),IF(F10>SUMIFS(Detalle!$H:$H,Detalle!$A:$A,$B$3,Detalle!$B:$B,$A10,Detalle!$D:$D,F$4),"▲",IF(F10<SUMIFS(Detalle!$H:$H,Detalle!$A:$A,$B$3,Detalle!$B:$B,$A10,Detalle!$D:$D,F$4),"▼","="))&" "&TEXT((F10-SUMIFS(Detalle!$H:$H,Detalle!$A:$A,$B$3,Detalle!$B:$B,$A10,Detalle!$D:$D,F$4))/SUMIFS(Detalle!$H:$H,Detalle!$A:$A,$B$3,Detalle!$B:$B,$A10,Detalle!$D:$D,F$4),"0.0%")) -> ▲ 20.9% | H10: =SUMIFS(Detalle!$G:$G,Detalle!$A:$A,$B$3,Detalle!$B:$B,$A10,Detalle!$D:$D,H$4) -> 1060551.2 | I10: =IF(SUMIFS(Detalle!$H:$H,Detalle!$A:$A,$B$3,Detalle!$B:$B,$A10,Detalle!$D:$D,H$4)<=0,IF(H10>0,"▲ nuevo","="),IF(H10>SUMIFS(Detalle!$H:$H,Detalle!$A:$A,$B$3,Detalle!$B:$B,$A10,Detalle!$D:$D,H$4),"▲",IF(H10<SUMIFS(Detalle!$H:$H,Detalle!$A:$A,$B$3,Detalle!$B:$B,$A10,Detalle!$D:$D,H$4),"▼","="))&" "&TEXT((H10-SUMIFS(Detalle!$H:$H,Detalle!$A:$A,$B$3,Detalle!$B:$B,$A10,Detalle!$D:$D,H$4))/SUMIFS(Detalle!$H:$H,Detalle!$A:$A,$B$3,Detalle!$B:$B,$A10,Detalle!$D:$D,H$4),"0.0%")) -> ▼ -10.3% | J10: =SUMIFS(Detalle!$G:$G,Detalle!$A:$A,$B$3,Detalle!$B:$B,$A10,Detalle!$D:$D,J$4) -> 1223088.1 | K10: =IF(SUMIFS(Detalle!$H:$H,Detalle!$A:$A,$B$3,Detalle!$B:$B,$A10,Detalle!$D:$D,J$4)<=0,IF(J10>0,"▲ nuevo","="),IF(J10>SUMIFS(Detalle!$H:$H,Detalle!$A:$A,$B$3,Detalle!$B:$B,$A10,Detalle!$D:$D,J$4),"▲",IF(J10<SUMIFS(Detalle!$H:$H,Detalle!$A:$A,$B$3,Detalle!$B:$B,$A10,Detalle!$D:$D,J$4),"▼","="))&" "&TEXT((J10-SUMIFS(Detalle!$H:$H,Detalle!$A:$A,$B$3,Detalle!$B:$B,$A10,Detalle!$D:$D,J$4))/SUMIFS(Detalle!$H:$H,Detalle!$A:$A,$B$3,Detalle!$B:$B,$A10,Detalle!$D:$D,J$4),"0.0%")) -> ▲ 15.3% | L10: =SUMIFS(Detalle!$G:$G,Detalle!$A:$A,$B$3,Detalle!$B:$B,$A10,Detalle!$D:$D,L$4) -> 1098779.2 | M10: =IF(SUMIFS(Detalle!$H:$H,Detalle!$A:$A,$B$3,Detalle!$B:$B,$A10,Detalle!$D:$D,L$4)<=0,IF(L10>0,"▲ nuevo","="),IF(L10>SUMIFS(Detalle!$H:$H,Detalle!$A:$A,$B$3,Detalle!$B:$B,$A10,Detalle!$D:$D,L$4),"▲",IF(L10<SUMIFS(Detalle!$H:$H,Detalle!$A:$A,$B$3,Detalle!$B:$B,$A10,Detalle!$D:$D,L$4),"▼","="))&" "&TEXT((L10-SUMIFS(Detalle!$H:$H,Detalle!$A:$A,$B$3,Detalle!$B:$B,$A10,Detalle!$D:$D,L$4))/SUMIFS(Detalle!$H:$H,Detalle!$A:$A,$B$3,Detalle!$B:$B,$A10,Detalle!$D:$D,L$4),"0.0%")) -> ▼ -10.2% | N10: =SUMIFS(Detalle!$G:$G,Detalle!$A:$A,$B$3,Detalle!$B:$B,$A10,Detalle!$D:$D,N$4) -> 1141700.1 | O10: =IF(SUMIFS(Detalle!$H:$H,Detalle!$A:$A,$B$3,Detalle!$B:$B,$A10,Detalle!$D:$D,N$4)<=0,IF(N10>0,"▲ nuevo","="),IF(N10>SUMIFS(Detalle!$H:$H,Detalle!$A:$A,$B$3,Detalle!$B:$B,$A10,Detalle!$D:$D,N$4),"▲",IF(N10<SUMIFS(Detalle!$H:$H,Detalle!$A:$A,$B$3,Detalle!$B:$B,$A10,Detalle!$D:$D,N$4),"▼","="))&" "&TEXT((N10-SUMIFS(Detalle!$H:$H,Detalle!$A:$A,$B$3,Detalle!$B:$B,$A10,Detalle!$D:$D,N$4))/SUMIFS(Detalle!$H:$H,Detalle!$A:$A,$B$3,Detalle!$B:$B,$A10,Detalle!$D:$D,N$4),"0.0%")) -> ▲ 3.9% | P10: =SUMIFS(Detalle!$G:$G,Detalle!$A:$A,$B$3,Detalle!$B:$B,$A10,Detalle!$D:$D,P$4) -> 1121146.1 | Q10: =IF(SUMIFS(Detalle!$H:$H,Detalle!$A:$A,$B$3,Detalle!$B:$B,$A10,Detalle!$D:$D,P$4)<=0,IF(P10>0,"▲ nuevo","="),IF(P10>SUMIFS(Detalle!$H:$H,Detalle!$A:$A,$B$3,Detalle!$B:$B,$A10,Detalle!$D:$D,P$4),"▲",IF(P10<SUMIFS(Detalle!$H:$H,Detalle!$A:$A,$B$3,Detalle!$B:$B,$A10,Detalle!$D:$D,P$4),"▼","="))&" "&TEXT((P10-SUMIFS(Detalle!$H:$H,Detalle!$A:$A,$B$3,Detalle!$B:$B,$A10,Detalle!$D:$D,P$4))/SUMIFS(Detalle!$H:$H,Detalle!$A:$A,$B$3,Detalle!$B:$B,$A10,Detalle!$D:$D,P$4),"0.0%")) -> ▼ -1.8%
A11: Eliezer Martinez (DN) | B11: =SUMIFS(Detalle!$G:$G,Detalle!$A:$A,$B$3,Detalle!$B:$B,$A11,Detalle!$D:$D,B$4) -> 914462.93 | C11: =IF(SUMIFS(Detalle!$H:$H,Detalle!$A:$A,$B$3,Detalle!$B:$B,$A11,Detalle!$D:$D,B$4)<=0,IF(B11>0,"▲ nuevo","="),IF(B11>SUMIFS(Detalle!$H:$H,Detalle!$A:$A,$B$3,Detalle!$B:$B,$A11,Detalle!$D:$D,B$4),"▲",IF(B11<SUMIFS(Detalle!$H:$H,Detalle!$A:$A,$B$3,Detalle!$B:$B,$A11,Detalle!$D:$D,B$4),"▼","="))&" "&TEXT((B11-SUMIFS(Detalle!$H:$H,Detalle!$A:$A,$B$3,Detalle!$B:$B,$A11,Detalle!$D:$D,B$4))/SUMIFS(Detalle!$H:$H,Detalle!$A:$A,$B$3,Detalle!$B:$B,$A11,Detalle!$D:$D,B$4),"0.0%")) -> ▼ -6.8% | D11: =SUMIFS(Detalle!$G:$G,Detalle!$A:$A,$B$3,Detalle!$B:$B,$A11,Detalle!$D:$D,D$4) -> 1003470.9 | E11: =IF(SUMIFS(Detalle!$H:$H,Detalle!$A:$A,$B$3,Detalle!$B:$B,$A11,Detalle!$D:$D,D$4)<=0,IF(D11>0,"▲ nuevo","="),IF(D11>SUMIFS(Detalle!$H:$H,Detalle!$A:$A,$B$3,Detalle!$B:$B,$A11,Detalle!$D:$D,D$4),"▲",IF(D11<SUMIFS(Detalle!$H:$H,Detalle!$A:$A,$B$3,Detalle!$B:$B,$A11,Detalle!$D:$D,D$4),"▼","="))&" "&TEXT((D11-SUMIFS(Detalle!$H:$H,Detalle!$A:$A,$B$3,Detalle!$B:$B,$A11,Detalle!$D:$D,D$4))/SUMIFS(Detalle!$H:$H,Detalle!$A:$A,$B$3,Detalle!$B:$B,$A11,Detalle!$D:$D,D$4),"0.0%")) -> ▲ 9.7% | F11: =SUMIFS(Detalle!$G:$G,Detalle!$A:$A,$B$3,Detalle!$B:$B,$A11,Detalle!$D:$D,F$4) -> 1019085.5 | G11: =IF(SUMIFS(Detalle!$H:$H,Detalle!$A:$A,$B$3,Detalle!$B:$B,$A11,Detalle!$D:$D,F$4)<=0,IF(F11>0,"▲ nuevo","="),IF(F11>SUMIFS(Detalle!$H:$H,Detalle!$A:$A,$B$3,Detalle!$B:$B,$A11,Detalle!$D:$D,F$4),"▲",IF(F11<SUMIFS(Detalle!$H:$H,Detalle!$A:$A,$B$3,Detalle!$B:$B,$A11,Detalle!$D:$D,F$4),"▼","="))&" "&TEXT((F11-SUMIFS(Detalle!$H:$H,Detalle!$A:$A,$B$3,Detalle!$B:$B,$A11,Detalle!$D:$D,F$4))/SUMIFS(Detalle!$H:$H,Detalle!$A:$A,$B$3,Detalle!$B:$B,$A11,Detalle!$D:$D,F$4),"0.0%")) -> ▲ 1.6% | H11: =SUMIFS(Detalle!$G:$G,Detalle!$A:$A,$B$3,Detalle!$B:$B,$A11,Detalle!$D:$D,H$4) -> 1007041.1 | I11: =IF(SUMIFS(Detalle!$H:$H,Detalle!$A:$A,$B$3,Detalle!$B:$B,$A11,Detalle!$D:$D,H$4)<=0,IF(H11>0,"▲ nuevo","="),IF(H11>SUMIFS(Detalle!$H:$H,Detalle!$A:$A,$B$3,Detalle!$B:$B,$A11,Detalle!$D:$D,H$4),"▲",IF(H11<SUMIFS(Detalle!$H:$H,Detalle!$A:$A,$B$3,Detalle!$B:$B,$A11,Detalle!$D:$D,H$4),"▼","="))&" "&TEXT((H11-SUMIFS(Detalle!$H:$H,Detalle!$A:$A,$B$3,Detalle!$B:$B,$A11,Detalle!$D:$D,H$4))/SUMIFS(Detalle!$H:$H,Detalle!$A:$A,$B$3,Detalle!$B:$B,$A11,Detalle!$D:$D,H$4),"0.0%")) -> ▼ -1.2% | J11: =SUMIFS(Detalle!$G:$G,Detalle!$A:$A,$B$3,Detalle!$B:$B,$A11,Detalle!$D:$D,J$4) -> 950019.58 | K11: =IF(SUMIFS(Detalle!$H:$H,Detalle!$A:$A,$B$3,Detalle!$B:$B,$A11,Detalle!$D:$D,J$4)<=0,IF(J11>0,"▲ nuevo","="),IF(J11>SUMIFS(Detalle!$H:$H,Detalle!$A:$A,$B$3,Detalle!$B:$B,$A11,Detalle!$D:$D,J$4),"▲",IF(J11<SUMIFS(Detalle!$H:$H,Detalle!$A:$A,$B$3,Detalle!$B:$B,$A11,Detalle!$D:$D,J$4),"▼","="))&" "&TEXT((J11-SUMIFS(Detalle!$H:$H,Detalle!$A:$A,$B$3,Detalle!$B:$B,$A11,Detalle!$D:$D,J$4))/SUMIFS(Detalle!$H:$H,Detalle!$A:$A,$B$3,Detalle!$B:$B,$A11,Detalle!$D:$D,J$4),"0.0%")) -> ▼ -5.7% | L11: =SUMIFS(Detalle!$G:$G,Detalle!$A:$A,$B$3,Detalle!$B:$B,$A11,Detalle!$D:$D,L$4) -> 943715.19 | M11: =IF(SUMIFS(Detalle!$H:$H,Detalle!$A:$A,$B$3,Detalle!$B:$B,$A11,Detalle!$D:$D,L$4)<=0,IF(L11>0,"▲ nuevo","="),IF(L11>SUMIFS(Detalle!$H:$H,Detalle!$A:$A,$B$3,Detalle!$B:$B,$A11,Detalle!$D:$D,L$4),"▲",IF(L11<SUMIFS(Detalle!$H:$H,Detalle!$A:$A,$B$3,Detalle!$B:$B,$A11,Detalle!$D:$D,L$4),"▼","="))&" "&TEXT((L11-SUMIFS(Detalle!$H:$H,Detalle!$A:$A,$B$3,Detalle!$B:$B,$A11,Detalle!$D:$D,L$4))/SUMIFS(Detalle!$H:$H,Detalle!$A:$A,$B$3,Detalle!$B:$B,$A11,Detalle!$D:$D,L$4),"0.0%")) -> ▼ -0.7% | N11: =SUMIFS(Detalle!$G:$G,Detalle!$A:$A,$B$3,Detalle!$B:$B,$A11,Detalle!$D:$D,N$4) -> 950875.27 | O11: =IF(SUMIFS(Detalle!$H:$H,Detalle!$A:$A,$B$3,Detalle!$B:$B,$A11,Detalle!$D:$D,N$4)<=0,IF(N11>0,"▲ nuevo","="),IF(N11>SUMIFS(Detalle!$H:$H,Detalle!$A:$A,$B$3,Detalle!$B:$B,$A11,Detalle!$D:$D,N$4),"▲",IF(N11<SUMIFS(Detalle!$H:$H,Detalle!$A:$A,$B$3,Detalle!$B:$B,$A11,Detalle!$D:$D,N$4),"▼","="))&" "&TEXT((N11-SUMIFS(Detalle!$H:$H,Detalle!$A:$A,$B$3,Detalle!$B:$B,$A11,Detalle!$D:$D,N$4))/SUMIFS(Detalle!$H:$H,Detalle!$A:$A,$B$3,Detalle!$B:$B,$A11,Detalle!$D:$D,N$4),"0.0%")) -> ▲ 0.8% | P11: =SUMIFS(Detalle!$G:$G,Detalle!$A:$A,$B$3,Detalle!$B:$B,$A11,Detalle!$D:$D,P$4) -> 952276.3 | Q11: =IF(SUMIFS(Detalle!$H:$H,Detalle!$A:$A,$B$3,Detalle!$B:$B,$A11,Detalle!$D:$D,P$4)<=0,IF(P11>0,"▲ nuevo","="),IF(P11>SUMIFS(Detalle!$H:$H,Detalle!$A:$A,$B$3,Detalle!$B:$B,$A11,Detalle!$D:$D,P$4),"▲",IF(P11<SUMIFS(Detalle!$H:$H,Detalle!$A:$A,$B$3,Detalle!$B:$B,$A11,Detalle!$D:$D,P$4),"▼","="))&" "&TEXT((P11-SUMIFS(Detalle!$H:$H,Detalle!$A:$A,$B$3,Detalle!$B:$B,$A11,Detalle!$D:$D,P$4))/SUMIFS(Detalle!$H:$H,Detalle!$A:$A,$B$3,Detalle!$B:$B,$A11,Detalle!$D:$D,P$4),"0.0%")) -> ▲ 0.1%
A12: Cristiano Perez (Mini Ma | B12: =SUMIFS(Detalle!$G:$G,Detalle!$A:$A,$B$3,Detalle!$B:$B,$A12,Detalle!$D:$D,B$4) -> 87466.73 | C12: =IF(SUMIFS(Detalle!$H:$H,Detalle!$A:$A,$B$3,Detalle!$B:$B,$A12,Detalle!$D:$D,B$4)<=0,IF(B12>0,"▲ nuevo","="),IF(B12>SUMIFS(Detalle!$H:$H,Detalle!$A:$A,$B$3,Detalle!$B:$B,$A12,Detalle!$D:$D,B$4),"▲",IF(B12<SUMIFS(Detalle!$H:$H,Detalle!$A:$A,$B$3,Detalle!$B:$B,$A12,Detalle!$D:$D,B$4),"▼","="))&" "&TEXT((B12-SUMIFS(Detalle!$H:$H,Detalle!$A:$A,$B$3,Detalle!$B:$B,$A12,Detalle!$D:$D,B$4))/SUMIFS(Detalle!$H:$H,Detalle!$A:$A,$B$3,Detalle!$B:$B,$A12,Detalle!$D:$D,B$4),"0.0%")) -> ▼ -17.2% | D12: =SUMIFS(Detalle!$G:$G,Detalle!$A:$A,$B$3,Detalle!$B:$B,$A12,Detalle!$D:$D,D$4) -> 128830.91 | E12: =IF(SUMIFS(Detalle!$H:$H,Detalle!$A:$A,$B$3,Detalle!$B:$B,$A12,Detalle!$D:$D,D$4)<=0,IF(D12>0,"▲ nuevo","="),IF(D12>SUMIFS(Detalle!$H:$H,Detalle!$A:$A,$B$3,Detalle!$B:$B,$A12,Detalle!$D:$D,D$4),"▲",IF(D12<SUMIFS(Detalle!$H:$H,Detalle!$A:$A,$B$3,Detalle!$B:$B,$A12,Detalle!$D:$D,D$4),"▼","="))&" "&TEXT((D12-SUMIFS(Detalle!$H:$H,Detalle!$A:$A,$B$3,Detalle!$B:$B,$A12,Detalle!$D:$D,D$4))/SUMIFS(Detalle!$H:$H,Detalle!$A:$A,$B$3,Detalle!$B:$B,$A12,Detalle!$D:$D,D$4),"0.0%")) -> ▲ 47.3% | F12: =SUMIFS(Detalle!$G:$G,Detalle!$A:$A,$B$3,Detalle!$B:$B,$A12,Detalle!$D:$D,F$4) -> 193894.46 | G12: =IF(SUMIFS(Detalle!$H:$H,Detalle!$A:$A,$B$3,Detalle!$B:$B,$A12,Detalle!$D:$D,F$4)<=0,IF(F12>0,"▲ nuevo","="),IF(F12>SUMIFS(Detalle!$H:$H,Detalle!$A:$A,$B$3,Detalle!$B:$B,$A12,Detalle!$D:$D,F$4),"▲",IF(F12<SUMIFS(Detalle!$H:$H,Detalle!$A:$A,$B$3,Detalle!$B:$B,$A12,Detalle!$D:$D,F$4),"▼","="))&" "&TEXT((F12-SUMIFS(Detalle!$H:$H,Detalle!$A:$A,$B$3,Detalle!$B:$B,$A12,Detalle!$D:$D,F$4))/SUMIFS(Detalle!$H:$H,Detalle!$A:$A,$B$3,Detalle!$B:$B,$A12,Detalle!$D:$D,F$4),"0.0%")) -> ▲ 50.5% | H12: =SUMIFS(Detalle!$G:$G,Detalle!$A:$A,$B$3,Detalle!$B:$B,$A12,Detalle!$D:$D,H$4) -> 141762.85 | I12: =IF(SUMIFS(Detalle!$H:$H,Detalle!$A:$A,$B$3,Detalle!$B:$B,$A12,Detalle!$D:$D,H$4)<=0,IF(H12>0,"▲ nuevo","="),IF(H12>SUMIFS(Detalle!$H:$H,Detalle!$A:$A,$B$3,Detalle!$B:$B,$A12,Detalle!$D:$D,H$4),"▲",IF(H12<SUMIFS(Detalle!$H:$H,Detalle!$A:$A,$B$3,Detalle!$B:$B,$A12,Detalle!$D:$D,H$4),"▼","="))&" "&TEXT((H12-SUMIFS(Detalle!$H:$H,Detalle!$A:$A,$B$3,Detalle!$B:$B,$A12,Detalle!$D:$D,H$4))/SUMIFS(Detalle!$H:$H,Detalle!$A:$A,$B$3,Detalle!$B:$B,$A12,Detalle!$D:$D,H$4),"0.0%")) -> ▼ -26.9% | J12: =SUMIFS(Detalle!$G:$G,Detalle!$A:$A,$B$3,Detalle!$B:$B,$A12,Detalle!$D:$D,J$4) -> 111372.9 | K12: =IF(SUMIFS(Detalle!$H:$H,Detalle!$A:$A,$B$3,Detalle!$B:$B,$A12,Detalle!$D:$D,J$4)<=0,IF(J12>0,"▲ nuevo","="),IF(J12>SUMIFS(Detalle!$H:$H,Detalle!$A:$A,$B$3,Detalle!$B:$B,$A12,Detalle!$D:$D,J$4),"▲",IF(J12<SUMIFS(Detalle!$H:$H,Detalle!$A:$A,$B$3,Detalle!$B:$B,$A12,Detalle!$D:$D,J$4),"▼","="))&" "&TEXT((J12-SUMIFS(Detalle!$H:$H,Detalle!$A:$A,$B$3,Detalle!$B:$B,$A12,Detalle!$D:$D,J$4))/SUMIFS(Detalle!$H:$H,Detalle!$A:$A,$B$3,Detalle!$B:$B,$A12,Detalle!$D:$D,J$4),"0.0%")) -> ▼ -21.4% | L12: =SUMIFS(Detalle!$G:$G,Detalle!$A:$A,$B$3,Detalle!$B:$B,$A12,Detalle!$D:$D,L$4) -> 103891.99 | M12: =IF(SUMIFS(Detalle!$H:$H,Detalle!$A:$A,$B$3,Detalle!$B:$B,$A12,Detalle!$D:$D,L$4)<=0,IF(L12>0,"▲ nuevo","="),IF(L12>SUMIFS(Detalle!$H:$H,Detalle!$A:$A,$B$3,Detalle!$B:$B,$A12,Detalle!$D:$D,L$4),"▲",IF(L12<SUMIFS(Detalle!$H:$H,Detalle!$A:$A,$B$3,Detalle!$B:$B,$A12,Detalle!$D:$D,L$4),"▼","="))&" "&TEXT((L12-SUMIFS(Detalle!$H:$H,Detalle!$A:$A,$B$3,Detalle!$B:$B,$A12,Detalle!$D:$D,L$4))/SUMIFS(Detalle!$H:$H,Detalle!$A:$A,$B$3,Detalle!$B:$B,$A12,Detalle!$D:$D,L$4),"0.0%")) -> ▼ -6.7% | N12: =SUMIFS(Detalle!$G:$G,Detalle!$A:$A,$B$3,Detalle!$B:$B,$A12,Detalle!$D:$D,N$4) -> 140055.94 | O12: =IF(SUMIFS(Detalle!$H:$H,Detalle!$A:$A,$B$3,Detalle!$B:$B,$A12,Detalle!$D:$D,N$4)<=0,IF(N12>0,"▲ nuevo","="),IF(N12>SUMIFS(Detalle!$H:$H,Detalle!$A:$A,$B$3,Detalle!$B:$B,$A12,Detalle!$D:$D,N$4),"▲",IF(N12<SUMIFS(Detalle!$H:$H,Detalle!$A:$A,$B$3,Detalle!$B:$B,$A12,Detalle!$D:$D,N$4),"▼","="))&" "&TEXT((N12-SUMIFS(Detalle!$H:$H,Detalle!$A:$A,$B$3,Detalle!$B:$B,$A12,Detalle!$D:$D,N$4))/SUMIFS(Detalle!$H:$H,Detalle!$A:$A,$B$3,Detalle!$B:$B,$A12,Detalle!$D:$D,N$4),"0.0%")) -> ▲ 34.8% | P12: =SUMIFS(Detalle!$G:$G,Detalle!$A:$A,$B$3,Detalle!$B:$B,$A12,Detalle!$D:$D,P$4) -> 180861.05 | Q12: =IF(SUMIFS(Detalle!$H:$H,Detalle!$A:$A,$B$3,Detalle!$B:$B,$A12,Detalle!$D:$D,P$4)<=0,IF(P12>0,"▲ nuevo","="),IF(P12>SUMIFS(Detalle!$H:$H,Detalle!$A:$A,$B$3,Detalle!$B:$B,$A12,Detalle!$D:$D,P$4),"▲",IF(P12<SUMIFS(Detalle!$H:$H,Detalle!$A:$A,$B$3,Detalle!$B:$B,$A12,Detalle!$D:$D,P$4),"▼","="))&" "&TEXT((P12-SUMIFS(Detalle!$H:$H,Detalle!$A:$A,$B$3,Detalle!$B:$B,$A12,Detalle!$D:$D,P$4))/SUMIFS(Detalle!$H:$H,Detalle!$A:$A,$B$3,Detalle!$B:$B,$A12,Detalle!$D:$D,P$4),"0.0%")) -> ▲ 29.1%
A13: TOTAL MINORISTA | B13: =SUMIFS(Detalle!$G:$G,Detalle!$A:$A,"Total",Detalle!$B:$B,"Minorista",Detalle!$D:$D,B$4) -> 11227031 | C13: =IF(SUMIFS(Detalle!$H:$H,Detalle!$A:$A,"Total",Detalle!$B:$B,"Minorista",Detalle!$D:$D,B$4)<=0,IF(B13>0,"▲ nuevo","="),IF(B13>SUMIFS(Detalle!$H:$H,Detalle!$A:$A,"Total",Detalle!$B:$B,"Minorista",Detalle!$D:$D,B$4),"▲",IF(B13<SUMIFS(Detalle!$H:$H,Detalle!$A:$A,"Total",Detalle!$B:$B,"Minorista",Detalle!$D:$D,B$4),"▼","="))&" "&TEXT((B13-SUMIFS(Detalle!$H:$H,Detalle!$A:$A,"Total",Detalle!$B:$B,"Minorista",Detalle!$D:$D,B$4))/SUMIFS(Detalle!$H:$H,Detalle!$A:$A,"Total",Detalle!$B:$B,"Minorista",Detalle!$D:$D,B$4),"0.0%")) -> ▼ -3.3% | D13: =SUMIFS(Detalle!$G:$G,Detalle!$A:$A,"Total",Detalle!$B:$B,"Minorista",Detalle!$D:$D,D$4) -> 11920827 | E13: =IF(SUMIFS(Detalle!$H:$H,Detalle!$A:$A,"Total",Detalle!$B:$B,"Minorista",Detalle!$D:$D,D$4)<=0,IF(D13>0,"▲ nuevo","="),IF(D13>SUMIFS(Detalle!$H:$H,Detalle!$A:$A,"Total",Detalle!$B:$B,"Minorista",Detalle!$D:$D,D$4),"▲",IF(D13<SUMIFS(Detalle!$H:$H,Detalle!$A:$A,"Total",Detalle!$B:$B,"Minorista",Detalle!$D:$D,D$4),"▼","="))&" "&TEXT((D13-SUMIFS(Detalle!$H:$H,Detalle!$A:$A,"Total",Detalle!$B:$B,"Minorista",Detalle!$D:$D,D$4))/SUMIFS(Detalle!$H:$H,Detalle!$A:$A,"Total",Detalle!$B:$B,"Minorista",Detalle!$D:$D,D$4),"0.0%")) -> ▲ 6.2% | F13: =SUMIFS(Detalle!$G:$G,Detalle!$A:$A,"Total",Detalle!$B:$B,"Minorista",Detalle!$D:$D,F$4) -> 13229334 | G13: =IF(SUMIFS(Detalle!$H:$H,Detalle!$A:$A,"Total",Detalle!$B:$B,"Minorista",Detalle!$D:$D,F$4)<=0,IF(F13>0,"▲ nuevo","="),IF(F13>SUMIFS(Detalle!$H:$H,Detalle!$A:$A,"Total",Detalle!$B:$B,"Minorista",Detalle!$D:$D,F$4),"▲",IF(F13<SUMIFS(Detalle!$H:$H,Detalle!$A:$A,"Total",Detalle!$B:$B,"Minorista",Detalle!$D:$D,F$4),"▼","="))&" "&TEXT((F13-SUMIFS(Detalle!$H:$H,Detalle!$A:$A,"Total",Detalle!$B:$B,"Minorista",Detalle!$D:$D,F$4))/SUMIFS(Detalle!$H:$H,Detalle!$A:$A,"Total",Detalle!$B:$B,"Minorista",Detalle!$D:$D,F$4),"0.0%")) -> ▲ 11.0% | H13: =SUMIFS(Detalle!$G:$G,Detalle!$A:$A,"Total",Detalle!$B:$B,"Minorista",Detalle!$D:$D,H$4) -> 11923421 | I13: =IF(SUMIFS(Detalle!$H:$H,Detalle!$A:$A,"Total",Detalle!$B:$B,"Minorista",Detalle!$D:$D,H$4)<=0,IF(H13>0,"▲ nuevo","="),IF(H13>SUMIFS(Detalle!$H:$H,Detalle!$A:$A,"Total",Detalle!$B:$B,"Minorista",Detalle!$D:$D,H$4),"▲",IF(H13<SUMIFS(Detalle!$H:$H,Detalle!$A:$A,"Total",Detalle!$B:$B,"Minorista",Detalle!$D:$D,H$4),"▼","="))&" "&TEXT((H13-SUMIFS(Detalle!$H:$H,Detalle!$A:$A,"Total",Detalle!$B:$B,"Minorista",Detalle!$D:$D,H$4))/SUMIFS(Detalle!$H:$H,Detalle!$A:$A,"Total",Detalle!$B:$B,"Minorista",Detalle!$D:$D,H$4),"0.0%")) -> ▼ -9.9% | J13: =SUMIFS(Detalle!$G:$G,Detalle!$A:$A,"Total",Detalle!$B:$B,"Minorista",Detalle!$D:$D,J$4) -> 12320136 | K13: =IF(SUMIFS(Detalle!$H:$H,Detalle!$A:$A,"Total",Detalle!$B:$B,"Minorista",Detalle!$D:$D,J$4)<=0,IF(J13>0,"▲ nuevo","="),IF(J13>SUMIFS(Detalle!$H:$H,Detalle!$A:$A,"Total",Detalle!$B:$B,"Minorista",Detalle!$D:$D,J$4),"▲",IF(J13<SUMIFS(Detalle!$H:$H,Detalle!$A:$A,"Total",Detalle!$B:$B,"Minorista",Detalle!$D:$D,J$4),"▼","="))&" "&TEXT((J13-SUMIFS(Detalle!$H:$H,Detalle!$A:$A,"Total",Detalle!$B:$B,"Minorista",Detalle!$D:$D,J$4))/SUMIFS(Detalle!$H:$H,Detalle!$A:$A,"Total",Detalle!$B:$B,"Minorista",Detalle!$D:$D,J$4),"0.0%")) -> ▲ 3.3% | L13: =SUMIFS(Detalle!$G:$G,Detalle!$A:$A,"Total",Detalle!$B:$B,"Minorista",Detalle!$D:$D,L$4) -> 11367430 | M13: =IF(SUMIFS(Detalle!$H:$H,Detalle!$A:$A,"Total",Detalle!$B:$B,"Minorista",Detalle!$D:$D,L$4)<=0,IF(L13>0,"▲ nuevo","="),IF(L13>SUMIFS(Detalle!$H:$H,Detalle!$A:$A,"Total",Detalle!$B:$B,"Minorista",Detalle!$D:$D,L$4),"▲",IF(L13<SUMIFS(Detalle!$H:$H,Detalle!$A:$A,"Total",Detalle!$B:$B,"Minorista",Detalle!$D:$D,L$4),"▼","="))&" "&TEXT((L13-SUMIFS(Detalle!$H:$H,Detalle!$A:$A,"Total",Detalle!$B:$B,"Minorista",Detalle!$D:$D,L$4))/SUMIFS(Detalle!$H:$H,Detalle!$A:$A,"Total",Detalle!$B:$B,"Minorista",Detalle!$D:$D,L$4),"0.0%")) -> ▼ -7.7% | N13: =SUMIFS(Detalle!$G:$G,Detalle!$A:$A,"Total",Detalle!$B:$B,"Minorista",Detalle!$D:$D,N$4) -> 11290560 | O13: =IF(SUMIFS(Detalle!$H:$H,Detalle!$A:$A,"Total",Detalle!$B:$B,"Minorista",Detalle!$D:$D,N$4)<=0,IF(N13>0,"▲ nuevo","="),IF(N13>SUMIFS(Detalle!$H:$H,Detalle!$A:$A,"Total",Detalle!$B:$B,"Minorista",Detalle!$D:$D,N$4),"▲",IF(N13<SUMIFS(Detalle!$H:$H,Detalle!$A:$A,"Total",Detalle!$B:$B,"Minorista",Detalle!$D:$D,N$4),"▼","="))&" "&TEXT((N13-SUMIFS(Detalle!$H:$H,Detalle!$A:$A,"Total",Detalle!$B:$B,"Minorista",Detalle!$D:$D,N$4))/SUMIFS(Detalle!$H:$H,Detalle!$A:$A,"Total",Detalle!$B:$B,"Minorista",Detalle!$D:$D,N$4),"0.0%")) -> ▼ -0.7% | P13: =SUMIFS(Detalle!$G:$G,Detalle!$A:$A,"Total",Detalle!$B:$B,"Minorista",Detalle!$D:$D,P$4) -> 11477013 | Q13: =IF(SUMIFS(Detalle!$H:$H,Detalle!$A:$A,"Total",Detalle!$B:$B,"Minorista",Detalle!$D:$D,P$4)<=0,IF(P13>0,"▲ nuevo","="),IF(P13>SUMIFS(Detalle!$H:$H,Detalle!$A:$A,"Total",Detalle!$B:$B,"Minorista",Detalle!$D:$D,P$4),"▲",IF(P13<SUMIFS(Detalle!$H:$H,Detalle!$A:$A,"Total",Detalle!$B:$B,"Minorista",Detalle!$D:$D,P$4),"▼","="))&" "&TEXT((P13-SUMIFS(Detalle!$H:$H,Detalle!$A:$A,"Total",Detalle!$B:$B,"Minorista",Detalle!$D:$D,P$4))/SUMIFS(Detalle!$H:$H,Detalle!$A:$A,"Total",Detalle!$B:$B,"Minorista",Detalle!$D:$D,P$4),"0.0%")) -> ▲ 1.7%
A14: Control: suma de filas − total (debe ser 0) | B14: =ROUND(SUM(B6:B12)-B13,0) -> 0 | D14: =ROUND(SUM(D6:D12)-D13,0) -> 0 | F14: =ROUND(SUM(F6:F12)-F13,0) -> 0 | H14: =ROUND(SUM(H6:H12)-H13,0) -> 0 | J14: =ROUND(SUM(J6:J12)-J13,0) -> 0 | L14: =ROUND(SUM(L6:L12)-L13,0) -> 0 | N14: =ROUND(SUM(N6:N12)-N13,0) -> 0 | P14: =ROUND(SUM(P6:P12)-P13,0) -> 0

Sheet Suplidor
A1: Ventas semanales por suplidor — Canal Minorista (pedidos)
A2: Monto neto sin ITBIS de pedidos (estatus 2/7/11). Semana lunes–domingo; la última (amarilla) es ESTIMADA: días transcurridos reales + promedio del mismo día de las últimas 4 semanas completas.
A3: Corte (clave en Detalle) | B3: Suplidor
A4: Inicio de semana (lunes) | B4: 46258 | D4: 46265 | F4: 46272 | H4: 46279 | J4: 46286 | L4: 46293 | N4: 46300 | P4: 46307
A5: Suplidor | B5: Sem 35 (24/08) | C5: vs sem. ant. | D5: Sem 36 (31/08) | E5: vs sem. ant. | F5: Sem 37 (07/09) | G5: vs sem. ant. | H5: Sem 38 (14/09) | I5: vs sem. ant. | J5: Sem 39 (21/09) | K5: vs sem. ant. | L5: Sem 40 (28/09) | M5: vs sem. ant. | N5: Sem 41 (05/10) | O5: vs sem. ant. | P5: Sem 42 (12/10) · EST. | Q5: vs sem. ant.
