Workbook

Sheet Instrucciones
B2: Formulario de Parametrizaciones — MovilBusiness Dashboard
B3: Aquí se anotan, en un solo lugar, todos los valores medibles que se deben configurar en el sistema (umbrales, pesos, metas, horas, colores, etc.).
B5: ¿Para qué sirve este formulario?
B6: Objetivo | C6: Reunir en un solo documento TODOS los valores que se pueden o se deben parametrizar en MovilBusiness Dashboard (AMCO-GT, Torre de Control, Geolocalizaciones, Visitas, Supervisión, Presupuestos, reportes, etc.). Con él, quien administra el sistema sabe exactamente qué configurar y con qué valores.
B7: Quién lo llena | C7: El responsable de la operación comercial de la empresa (Gerencia / Dirección de ventas). No necesita conocimientos técnicos: solo escribir los valores que desea en las celdas amarillas.
B8: Qué NO es | C8: No es un formulario de datos de clientes ni de ventas. Solo recoge reglas de medición (cuánto vale cada indicador, desde qué hora, qué porcentaje es verde o rojo, etc.).
B10: Cómo llenarlo, paso a paso
B11: Paso 1 | C11: Vaya a la hoja «Datos generales» y escriba el nombre de la empresa, quién llena el formulario y la fecha.
B12: Paso 2 | C12: Recorra las hojas numeradas (1, 2, 3 …) en orden. Cada hoja es un módulo del sistema y tiene una descripción arriba.
B13: Paso 3 | C13: En cada fila lea la columna «Qué controla» y fíjese en el «Valor actual (por defecto)» y en el rango «DESDE – HASTA».
B14: Paso 4 | C14: Escriba en la celda AMARILLA («VALOR A CONFIGURAR») el valor que desea. Si quiere dejar el valor actual, escriba ese mismo valor. Si una fila no aplica a su empresa, déjela en blanco y anótelo en «Datos generales → Observaciones».
B15: Paso 5 | C15: Mire la columna «Estado»: OK (dentro del rango), Fuera de rango (corregir) o Pendiente (sin llenar). La hoja «Resumen» le muestra el avance total.
B16: Paso 6 | C16: Cuando termine, guarde el archivo y envíelo al administrador del sistema para que aplique los valores. No cambie los nombres de las hojas ni inserte/borre columnas.
B18: Cómo leer las columnas de cada hoja
B19: Pantalla / apartado | C19: Dónde se ve o se configura ese valor dentro del sistema.
B20: Parámetro y Qué controla | C20: El nombre del valor y, en una frase, para qué sirve.
B21: Unidad | C21: En qué se mide: % (escriba 85 para 85 %), minutos, metros, km, RD$, puntos, factor (1.05 = +5 %), hh:mm (hora, ej. 08:15), texto o lista.
B22: Valor actual (por defecto) | C22: Con qué valor viene hoy el sistema. Es la referencia: si no desea cambiarlo, repita ese valor.
B23: VALOR A CONFIGURAR | C23: La ÚNICA celda que usted llena (amarilla). Las listas desplegables ofrecen las opciones permitidas.
B24: Rango DESDE / HASTA | C24: Los valores mínimo y máximo que se aceptan. Si escribe algo fuera del rango, Excel lo avisa y el Estado sale «Fuera de rango».
B25: Tipo de rango | C25: «Validado» = el sistema mismo rechaza valores fuera de ese rango. «Sugerido» = el sistema no lo comprueba; el rango lo propone este formulario como valor razonable (se puede ajustar con criterio de negocio). «Lista» = solo opciones fijas.
B26: Cómo llenarlo / ejemplo | C26: Una explicación corta, con ejemplos y reglas entre valores (por ejemplo, «el corte A debe ser mayor que el corte B»).
B27: Dónde se configura | C27: Pantalla o tabla donde se aplica y su ALCANCE: «Por usuario/navegador» (cada computadora guarda su propio valor y hay que configurarla en cada una), «Global (BD)» (un valor para toda la empresa, lo aplica Gerencia/TI) o «Fijo en código» (hoy no se edita en pantalla; aplicarlo requiere una modificación del programa).
B29: Formatos y reglas generales
B30: Porcentajes | C30: Escriba el número sin el signo %: para 85 % escriba 85. (Excepción: en la hoja «6b Metas de activación» sí se escribe con el signo, ej. 25 %.)
B31: Horas | C31: Formato hh:mm de 24 horas. Ejemplos: 08:15 es las 8:15 a. m.; 15:30 es las 3:30 p. m. El sistema las guarda internamente como minutos desde la medianoche (08:15 = 495); la conversión la hace quien aplica los valores.
B32: Factores | C32: Son multiplicadores. 1.00 = sin cambio; 1.05 = +5 %; 0.95 = −5 %. Use punto o coma decimal según la configuración de su Excel.
B33: Pesos | C33: Los pesos de un mismo grupo deben sumar 100. Cada grupo tiene una fila «Suma de pesos» que se calcula sola y le dice si cuadra.
B34: Coherencia entre valores | C34: Varios parámetros dependen entre sí (por ejemplo: corte para nota 100 > corte para nota 75 > corte para nota 50; hora de nota 100 anterior a la hora de nota 0). Cada fila lo recuerda en «Cómo llenarlo».
B35: Hoja «8 Fijos en código» | C35: Reúne valores que hoy NO se pueden cambiar en pantalla (escalas de color, tiempos de refresco, seguridad). Anote ahí el valor que desearía: se tratará como solicitud de cambio.
B37: Hojas de este formulario
B38: Datos generales | C38: Empresa, responsable, fecha y observaciones.
B39: Resumen | C39: Avance automático: cuántos parámetros están OK, pendientes o fuera de rango.
B40: 1 AMCO-GT | C40: Pesos, cortes de nota, horas y bandas del índice AMCO-GT (módulo Seguimientos) y metas por suplidor.
B41: 2 Torre de Control | C41: Ventana de vigilancia, tiempo de silencio y umbral/severidad de cada monitor de alertas, más monitores personalizados.
B42: 3 Geolocalizaciones | C42: Colores por tiempo sin sincronizar y por cercanía a la ruta en el mapa.
B43: 4 Home-Visitas | C43: Horas límite de «primera visita a tiempo» y «primer pedido a tiempo».
B44: 5 Supervisión | C44: Pesos del Índice Global, factores de acompañamiento y auditoría, umbrales y metas de Cobros del día, cronograma semanal.
B45: 6 Presupuesto-Gestión | C45: Variables del motor de presupuesto (factores, metas rappel, pisos, topes, umbrales).
B46: 6b Metas de activación | C46: Meta de activación por suplidor y categoría (precargada con los valores vigentes).
...

Sheet Datos generales
B2: Datos generales
B3: Escriba quién llena el formulario y para qué empresa. Esta hoja es individual: no lleva logos.
B5: Dato | C5: Valor (llenar) | D5: Cómo llenarlo
B6: Empresa | D6: Nombre de la empresa para la que se configura el sistema.
B7: Responsable que llena el formulario | D7: Nombre y apellido.
B8: Cargo | D8: Cargo de quien llena el formulario.
B9: Correo / teléfono de contacto | D9: Para aclarar dudas sobre los valores.
B10: Fecha de llenado | D10: Fecha en que se completó (dd/mm/aaaa).
B11: Versión del sistema | D11: Opcional. Se ve en la dirección /version del sistema (ej. 1.14.0).
B12: Observaciones | D12: Anote aquí lo que no aplica a su empresa o cualquier aclaración.

Sheet Resumen
B2: Avance del formulario
B3: Se actualiza solo a medida que se llenan las hojas. Meta: Pendientes = 0 y Fuera de rango = 0.
B5: Hoja | C5: Parámetros | D5: OK | E5: Pendientes | F5: Fuera de rango
B6: 1 AMCO-GT | C6: =COUNTA('1 AMCO-GT'!C6:C40) -> 28 | D6: =COUNTIF('1 AMCO-GT'!K6:K40,"OK") -> 0 | E6: =COUNTIF('1 AMCO-GT'!K6:K40,"Pendiente") -> 28 | F6: =COUNTIF('1 AMCO-GT'!K6:K40,"Fuera de rango") -> 0
B7: 2 Torre de Control | C7: =COUNTA('2 Torre de Control'!C6:C48) -> 41 | D7: =COUNTIF('2 Torre de Control'!K6:K48,"OK") -> 0 | E7: =COUNTIF('2 Torre de Control'!K6:K48,"Pendiente") -> 41 | F7: =COUNTIF('2 Torre de Control'!K6:K48,"Fuera de rango") -> 0
B8: 3 Geolocalizaciones | C8: =COUNTA('3 Geolocalizaciones'!C6:C12) -> 5 | D8: =COUNTIF('3 Geolocalizaciones'!K6:K12,"OK") -> 0 | E8: =COUNTIF('3 Geolocalizaciones'!K6:K12,"Pendiente") -> 5 | F8: =COUNTIF('3 Geolocalizaciones'!K6:K12,"Fuera de rango") -> 0
B9: 4 Home-Visitas | C9: =COUNTA('4 Home-Visitas'!C6:C7) -> 2 | D9: =COUNTIF('4 Home-Visitas'!K6:K7,"OK") -> 0 | E9: =COUNTIF('4 Home-Visitas'!K6:K7,"Pendiente") -> 2 | F9: =COUNTIF('4 Home-Visitas'!K6:K7,"Fuera de rango") -> 0
B10: 5 Supervisión | C10: =COUNTA('5 Supervisión'!C6:C45) -> 34 | D10: =COUNTIF('5 Supervisión'!K6:K45,"OK") -> 0 | E10: =COUNTIF('5 Supervisión'!K6:K45,"Pendiente") -> 34 | F10: =COUNTIF('5 Supervisión'!K6:K45,"Fuera de rango") -> 0
B11: 6 Presupuesto-Gestión | C11: =COUNTA('6 Presupuesto-Gestión'!C6:C21) -> 14 | D11: =COUNTIF('6 Presupuesto-Gestión'!K6:K21,"OK") -> 0 | E11: =COUNTIF('6 Presupuesto-Gestión'!K6:K21,"Pendiente") -> 14 | F11: =COUNTIF('6 Presupuesto-Gestión'!K6:K21,"Fuera de rango") -> 0
B12: 6b Metas de activación | C12: =COUNTA('6b Metas de activación'!B6:B48) -> 31 | D12: =COUNTIF('6b Metas de activación'!I6:I48,"OK") -> 0 | E12: =COUNTIF('6b Metas de activación'!I6:I48,"Pendiente") -> 43 | F12: =COUNTIF('6b Metas de activación'!I6:I48,"Fuera de rango") -> 0
B13: 7 Reportes y envíos | C13: =COUNTA('7 Reportes y envíos'!C6:C9) -> 4 | D13: =COUNTIF('7 Reportes y envíos'!K6:K9,"OK") -> 0 | E13: =COUNTIF('7 Reportes y envíos'!K6:K9,"Pendiente") -> 4 | F13: =COUNTIF('7 Reportes y envíos'!K6:K9,"Fuera de rango") -> 0
B14: 8 Fijos en código | C14: =COUNTA('8 Fijos en código'!C6:C43) -> 34 | D14: =COUNTIF('8 Fijos en código'!K6:K43,"OK") -> 0 | E14: =COUNTIF('8 Fijos en código'!K6:K43,"Pendiente") -> 34 | F14: =COUNTIF('8 Fijos en código'!K6:K43,"Fuera de rango") -> 0
B15: TOTAL | C15: =SUM(C6:C14) -> 193 | D15: =SUM(D6:D14) -> 0 | E15: =SUM(E6:E14) -> 205 | F15: =SUM(F6:F14) -> 0
B17: Porcentaje completado | C17: =IF(C15=0,0,D15/C15) -> 0

Sheet 1 AMCO-GT
A1: 1 · AMCO-GT (Índice de Eficiencia de la Gestión del Tiempo)
A2: Cómo se puntúa cada vendedor de 0 a 100: pesos de los 7 indicadores, cortes de nota, horas y bandas (Sólida / Aceptable / Irregular / Deficiente).
A3: Los pesos se normalizan por su suma, pero el formulario pide que sumen 100. Los indicadores usan rampa lineal entre cortes (no escalones).
A5: # | B5: Pantalla / apartado | C5: Parámetro | D5: Qué controla | E5: Unidad | F5: Valor actual (por defecto) | G5: VALOR A CONFIGURAR (llenar) | H5: Rango DESDE | I5: Rango HASTA | J5: Tipo de rango | K5: Estado | L5: Cómo llenarlo / ejemplo | M5: Dónde se configura (y alcance)
A6: A. Pesos de los 7 indicadores (deben sumar 100)
A7: 1 | B7: Seguimientos | C7: Peso · Cumplimiento de ruta | D7: Cuánto vale de los 100 puntos haber visitado los clientes programados. | E7: % | F7: 30 | H7: 0 | I7: 100 | J7: Sugerido | K7: =IF(G7="","Pendiente",IF(AND(ISNUMBER(G7),G7>=H7,G7<=I7),"OK","Fuera de rango")) -> Pendiente | L7: Escriba un número entre 0 y 100. Hoy es el indicador más pesado. | M7: Seguimientos → ⚙ Configuración (modal «Configuración de parámetros»). Alcance: por usuario/navegador.
A8: 2 | B8: Seguimientos | C8: Peso · Inicio temprano (Primer Pedido) | D8: Cuánto vale tomar el primer pedido temprano. | E8: % | F8: 20 | H8: 0 | I8: 100 | J8: Sugerido | K8: =IF(G8="","Pendiente",IF(AND(ISNUMBER(G8),G8>=H8,G8<=I8),"OK","Fuera de rango")) -> Pendiente | L8: Mide la hora promedio del primer pedido del día. | M8: Seguimientos → ⚙ Configuración (modal «Configuración de parámetros»). Alcance: por usuario/navegador.
A9: 3 | B9: Seguimientos | C9: Peso · Cierre no prematuro (Último Pedido) | D9: Cuánto vale no terminar de vender demasiado temprano. | E9: % | F9: 10 | H9: 0 | I9: 100 | J9: Sugerido | K9: =IF(G9="","Pendiente",IF(AND(ISNUMBER(G9),G9>=H9,G9<=I9),"OK","Fuera de rango")) -> Pendiente | L9: Mide la hora promedio del último pedido del día. | M9: Seguimientos → ⚙ Configuración (modal «Configuración de parámetros»). Alcance: por usuario/navegador.
A10: 4 | B10: Seguimientos | C10: Peso · Efectividad de ventas | D10: Cuánto vale la proporción de clientes visitados con pedido. | E10: % | F10: 10 | H10: 0 | I10: 100 | J10: Sugerido | K10: =IF(G10="","Pendiente",IF(AND(ISNUMBER(G10),G10>=H10,G10<=I10),"OK","Fuera de rango")) -> Pendiente | L10: Pedidos ÷ visitados. | M10: Seguimientos → ⚙ Configuración (modal «Configuración de parámetros»). Alcance: por usuario/navegador.
A11: 5 | B11: Seguimientos | C11: Peso · Disciplina de ruta | D11: Cuánto vale no tomar pedidos a clientes que no tocaban ese día. | E11: % | F11: 10 | H11: 0 | I11: 100 | J11: Sugerido | K11: =IF(G11="","Pendiente",IF(AND(ISNUMBER(G11),G11>=H11,G11<=I11),"OK","Fuera de rango")) -> Pendiente | L11: Cuenta clientes de otro día o fuera de su ruta. | M11: Seguimientos → ⚙ Configuración (modal «Configuración de parámetros»). Alcance: por usuario/navegador.
A12: 6 | B12: Seguimientos | C12: Peso · Consistencia PDV | D12: Cuánto vale registrar la visita dentro del punto de venta (GPS). | E12: % | F12: 10 | H12: 0 | I12: 100 | J12: Sugerido | K12: =IF(G12="","Pendiente",IF(AND(ISNUMBER(G12),G12>=H12,G12<=I12),"OK","Fuera de rango")) -> Pendiente | L12: Cuenta visitas marcadas lejos del cliente. | M12: Seguimientos → ⚙ Configuración (modal «Configuración de parámetros»). Alcance: por usuario/navegador.
A13: 7 | B13: Seguimientos | C13: Peso · Ritmo de visita | D13: Cuánto vale mantener un tiempo de visita similar al del grupo. | E13: % | F13: 10 | H13: 0 | I13: 100 | J13: Sugerido | K13: =IF(G13="","Pendiente",IF(AND(ISNUMBER(G13),G13>=H13,G13<=I13),"OK","Fuera de rango")) -> Pendiente | L13: Compara el tiempo por visita contra la mediana del grupo. | M13: Seguimientos → ⚙ Configuración (modal «Configuración de parámetros»). Alcance: por usuario/navegador.
C14: Suma de pesos (debe ser 100) | D14: Se calcula sola con los 7 pesos de arriba. | E14: % | F14: 100 | G14: =SUM(G7:G13) -> 0 | H14: 100 | I14: 100 | J14: Calculado | K14: =IF(COUNT(G7:G13)=0,"Pendiente",IF(ROUND(G14,4)=100,"OK","Fuera de rango")) -> Pendiente | L14: No se llena: se calcula solo.
A15: B. Cumplimiento de ruta — cortes de nota (visitados ÷ a visitar)
A16: 8 | B16: Seguimientos | C16: Cumplimiento ≥ para nota 100 | D16: Porcentaje de cumplimiento desde el cual el vendedor obtiene nota 100. | E16: % | F16: 98 | H16: 0 | I16: 100 | J16: Sugerido | K16: =IF(G16="","Pendiente",IF(AND(ISNUMBER(G16),G16>=H16,G16<=I16),"OK","Fuera de rango")) -> Pendiente | L16: Debe ser MAYOR que los dos cortes siguientes. | M16: Seguimientos → ⚙ Configuración (modal «Configuración de parámetros»). Alcance: por usuario/navegador.
A17: 9 | B17: Seguimientos | C17: Cumplimiento ≥ para nota 75 | D17: Porcentaje con el que se obtiene nota 75. | E17: % | F17: 95 | H17: 0 | I17: 100 | J17: Sugerido | K17: =IF(G17="","Pendiente",IF(AND(ISNUMBER(G17),G17>=H17,G17<=I17),"OK","Fuera de rango")) -> Pendiente | L17: Debe ser menor que el corte de 100 y mayor que el de 50. | M17: Seguimientos → ⚙ Configuración (modal «Configuración de parámetros»). Alcance: por usuario/navegador.
A18: 10 | B18: Seguimientos | C18: Cumplimiento ≥ para nota 50 | D18: Porcentaje con el que se obtiene nota 50 (debajo, la nota sigue bajando hasta 0). | E18: % | F18: 88 | H18: 0 | I18: 100 | J18: Sugerido | K18: =IF(G18="","Pendiente",IF(AND(ISNUMBER(G18),G18>=H18,G18<=I18),"OK","Fuera de rango")) -> Pendiente | L18: Debe ser el MENOR de los tres cortes. | M18: Seguimientos → ⚙ Configuración (modal «Configuración de parámetros»). Alcance: por usuario/navegador.
A19: C. Inicio temprano (hora del primer pedido) y Cierre no prematuro (hora del último pedido)
A20: 11 | B20: Seguimientos | C20: Primer pedido ≤ para nota 100 | D20: Hora límite del primer pedido para obtener nota 100. | E20: hh:mm | F20: 0.34375 | H20: 0.25 | I20: 0.5 | J20: Sugerido | K20: =IF(G20="","Pendiente",IF(AND(ISNUMBER(G20),G20>=H20,G20<=I20),"OK","Fuera de rango")) -> Pendiente | L20: Ej. 08:15. Todo primer pedido a esa hora o antes saca 100. | M20: Seguimientos → ⚙ Configuración (modal «Configuración de parámetros»). Alcance: por usuario/navegador.
A21: 12 | B21: Seguimientos | C21: Primer pedido: hora de nota 0 | D21: Hora a partir de la cual la nota de inicio es 0 (entre las dos horas baja de forma pareja). En pantalla aparece como «Inicio ≤ para 50», pero en realidad es el punto de nota 0. | E21: hh:mm | F21: 0.36458333 | H21: 0.25 | I21: 0.54166667 | J21: Sugerido | K21: =IF(G21="","Pendiente",IF(AND(ISNUMBER(G21),G21>=H21,G21<=I21),"OK","Fuera de rango")) -> Pendiente | L21: Debe ser POSTERIOR a la hora de nota 100 (ej. 08:45). | M21: Seguimientos → ⚙ Configuración (modal «Configuración de parámetros»). Alcance: por usuario/navegador.
A22: 13 | B22: Seguimientos | C22: Último pedido ≥ para nota 100 | D22: Hora del último pedido desde la cual se obtiene nota 100. | E22: hh:mm | F22: 0.64583333 | H22: 0.5 | I22: 0.75 | J22: Sugerido | K22: =IF(G22="","Pendiente",IF(AND(ISNUMBER(G22),G22>=H22,G22<=I22),"OK","Fuera de rango")) -> Pendiente | L22: Ej. 15:30. Un último pedido a esa hora o después saca 100. | M22: Seguimientos → ⚙ Configuración (modal «Configuración de parámetros»). Alcance: por usuario/navegador.
A23: 14 | B23: Seguimientos | C23: Último pedido: hora de nota 0 | D23: Hora por debajo de la cual la nota de cierre es 0. En pantalla aparece como «Cierre ≥ para 50», pero es el punto de nota 0. | E23: hh:mm | F23: 0.60416667 | H23: 0.45833333 | I23: 0.70833333 | J23: Sugerido | K23: =IF(G23="","Pendiente",IF(AND(ISNUMBER(G23),G23>=H23,G23<=I23),"OK","Fuera de rango")) -> Pendiente | L23: Debe ser ANTERIOR a la hora de nota 100 (ej. 14:30). | M23: Seguimientos → ⚙ Configuración (modal «Configuración de parámetros»). Alcance: por usuario/navegador.
A24: D. Efectividad de ventas (pedidos ÷ visitados)
A25: 15 | B25: Seguimientos | C25: Banda ideal — mínimo | D25: Efectividad mínima de la banda que da nota 100. | E25: % | F25: 55 | H25: 0 | I25: 100 | J25: Sugerido | K25: =IF(G25="","Pendiente",IF(AND(ISNUMBER(G25),G25>=H25,G25<=I25),"OK","Fuera de rango")) -> Pendiente | L25: Escriba 55 para 55 %. | M25: Seguimientos → ⚙ Configuración (modal «Configuración de parámetros»). Alcance: por usuario/navegador.
A26: 16 | B26: Seguimientos | C26: Banda ideal — máximo | D26: Efectividad máxima de la banda que da nota 100. | E26: % | F26: 65 | H26: 0 | I26: 100 | J26: Sugerido | K26: =IF(G26="","Pendiente",IF(AND(ISNUMBER(G26),G26>=H26,G26<=I26),"OK","Fuera de rango")) -> Pendiente | L26: Debe ser mayor o igual al mínimo. Fuera de la banda la nota baja por ambos lados. | M26: Seguimientos → ⚙ Configuración (modal «Configuración de parámetros»). Alcance: por usuario/navegador.
A27: 17 | B27: Seguimientos | C27: Tolerancia fuera de banda | D27: Puntos porcentuales fuera de la banda hasta llegar a nota 60. | E27: puntos % | F27: 5 | H27: 1 | I27: 20 | J27: Sugerido | K27: =IF(G27="","Pendiente",IF(AND(ISNUMBER(G27),G27>=H27,G27<=I27),"OK","Fuera de rango")) -> Pendiente | L27: No use 0 (el cálculo se rompe). Ej. 5. | M27: Seguimientos → ⚙ Configuración (modal «Configuración de parámetros»). Alcance: por usuario/navegador.
A28: E. Bandas de resultado del AMCO-GT (puntos de 0 a 100)
A29: 18 | B29: Seguimientos | C29: Banda Sólida desde | D29: Puntaje mínimo para clasificar como Sólida. | E29: puntos | F29: 85 | H29: 0 | I29: 100 | J29: Sugerido | K29: =IF(G29="","Pendiente",IF(AND(ISNUMBER(G29),G29>=H29,G29<=I29),"OK","Fuera de rango")) -> Pendiente | L29: Debe ser mayor que Aceptable. | M29: Seguimientos → ⚙ Configuración (modal «Configuración de parámetros»). Alcance: por usuario/navegador.
A30: 19 | B30: Seguimientos | C30: Banda Aceptable desde | D30: Puntaje mínimo para clasificar como Aceptable. | E30: puntos | F30: 70 | H30: 0 | I30: 100 | J30: Sugerido | K30: =IF(G30="","Pendiente",IF(AND(ISNUMBER(G30),G30>=H30,G30<=I30),"OK","Fuera de rango")) -> Pendiente | L30: Entre Sólida e Irregular. | M30: Seguimientos → ⚙ Configuración (modal «Configuración de parámetros»). Alcance: por usuario/navegador.
A31: 20 | B31: Seguimientos | C31: Banda Irregular desde | D31: Puntaje mínimo para Irregular; por debajo es Deficiente. | E31: puntos | F31: 55 | H31: 0 | I31: 100 | J31: Sugerido | K31: =IF(G31="","Pendiente",IF(AND(ISNUMBER(G31),G31>=H31,G31<=I31),"OK","Fuera de rango")) -> Pendiente | L31: Debe ser el menor de los tres cortes. | M31: Seguimientos → ⚙ Configuración (modal «Configuración de parámetros»). Alcance: por usuario/navegador.
A32: F. Consistencia en el punto de venta (Fuera de PDV)
A33: 21 | B33: Seguimientos | C33: Modo de medición «Fuera de PDV» | D33: Cómo se detecta una visita fuera del punto de venta. | E33: lista | F33: distancia | H33: Lista | I33: distancia / ruta | J33: Lista | K33: =IF(G33="","Pendiente","OK") -> Pendiente | L33: «distancia» = el GPS de la visita queda lejos del cliente; «ruta» = cliente no programado ese día. | M33: Seguimientos → ⚙ Configuración (modal «Configuración de parámetros»). Alcance: por usuario/navegador.
A34: 22 | B34: Seguimientos | C34: Distancia máxima GPS al cliente | D34: Metros entre la ubicación de la visita y el cliente a partir de los cuales cuenta como «fuera de PDV» (modo distancia). | E34: metros | F34: 200 | H34: 20 | I34: 5000 | J34: Validado | K34: =IF(G34="","Pendiente",IF(AND(ISNUMBER(G34),G34>=H34,G34<=I34),"OK","Fuera de rango")) -> Pendiente | L34: El sistema solo acepta de 20 a 5000 m; fuera de eso vuelve a 200. | M34: Seguimientos → ⚙ Configuración (modal «Configuración de parámetros»). Alcance: por usuario/navegador.
A35: G. Metas por Suplidor / Categoría / Producto (Seguimientos → modo «Por Suplidor»)
A36: 23 | B36: Seguimientos · Por Suplidor | C36: Meta de venta por vendedor y semana (ValorSemVend) | D36: Denominador del «cumplimiento de meta» por ítem. Por defecto es el promedio semanal de las últimas 13 semanas. | E36: RD$ | F36: Promedio 13 sem. | H36: 0 | I36: 100000000 | J36: Sugerido | K36: =IF(G36="","Pendiente",IF(AND(ISNUMBER(G36),G36>=H36,G36<=I36),"OK","Fuera de rango")) -> Pendiente | L36: Se edita por ítem dentro de la pantalla «Por Suplidor». Anote aquí la regla general o los casos especiales. | M36: Seguimientos → Por Suplidor. Tabla SeguimientoParametros_RM. Alcance: global (BD).
A37: 24 | B37: Seguimientos · Por Suplidor | C37: Meta en unidades por vendedor y semana (UnidadesSemVend) | D37: Meta en unidades por ítem. | E37: unidades | F37: Promedio 13 sem. | H37: 0 | I37: 1000000 | J37: Sugerido | K37: =IF(G37="","Pendiente",IF(AND(ISNUMBER(G37),G37>=H37,G37<=I37),"OK","Fuera de rango")) -> Pendiente | L37: Hoy no tiene pantalla: se aplica por el administrador (API/BD). | M37: Tabla SeguimientoParametros_RM. Alcance: global (BD).
A38: 25 | B38: Seguimientos · Por Suplidor | C38: Meta en cajas por vendedor y semana (CajasSemVend) | D38: Meta en cajas por ítem. | E38: cajas | F38: Promedio 13 sem. | H38: 0 | I38: 1000000 | J38: Sugerido | K38: =IF(G38="","Pendiente",IF(AND(ISNUMBER(G38),G38>=H38,G38<=I38),"OK","Fuera de rango")) -> Pendiente | L38: Hoy no tiene pantalla: se aplica por el administrador (API/BD). | M38: Tabla SeguimientoParametros_RM. Alcance: global (BD).
A39: 26 | B39: Seguimientos · Por Suplidor | C39: Objetivo de efectividad por ítem (EfectividadObj) | D39: Efectividad objetivo por ítem (hoy ninguna pantalla lo usa). | E39: % | F39: vacío | H39: 0 | I39: 100 | J39: Sugerido | K39: =IF(G39="","Pendiente",IF(AND(ISNUMBER(G39),G39>=H39,G39<=I39),"OK","Fuera de rango")) -> Pendiente | L39: Opcional. | M39: Tabla SeguimientoParametros_RM. Alcance: global (BD).
A40: 27 | B40: Seguimientos · Por Suplidor | C40: Semanas de histórico para calcular la meta base | D40: Cuántas semanas hacia atrás se promedian para proponer la meta. | E40: semanas | F40: 13 | H40: 4 | I40: 52 | J40: Sugerido | K40: =IF(G40="","Pendiente",IF(AND(ISNUMBER(G40),G40>=H40,G40<=I40),"OK","Fuera de rango")) -> Pendiente | L40: Se cambia re-corriendo el script SQL de parámetros. | M40: SQL/SeguimientoParametros_RM.sql. Alcance: global (BD).

Sheet 2 Torre de Control
A1: 2 · Torre de Control (alertas en vivo)
A2: Horario de vigilancia, minutos de silencio tras un contacto y la regla (umbral, severidad y encendido) de cada monitor de alertas.
A3: Nota: el sistema solo lee el «umbral» de cada monitor; el intervalo de 30 min entre cortes es fijo (:00 y :30). La hora 08:20 equivale a 500 minutos desde medianoche.
A5: # | B5: Pantalla / apartado | C5: Parámetro | D5: Qué controla | E5: Unidad | F5: Valor actual (por defecto) | G5: VALOR A CONFIGURAR (llenar) | H5: Rango DESDE | I5: Rango HASTA | J5: Tipo de rango | K5: Estado | L5: Cómo llenarlo / ejemplo | M5: Dónde se configura (y alcance)
A6: 1 | B6: Torre · Ventana | C6: Ventana: desde | D6: Hora en que empieza la vigilancia y los cortes (snapshots) del día; base del ritmo del monitor de Cumplimiento. | E6: hh:mm | F6: 0.34722222 | H6: 0.25 | I6: 0.5 | J6: Sugerido | K6: =IF(G6="","Pendiente",IF(AND(ISNUMBER(G6),G6>=H6,G6<=I6),"OK","Fuera de rango")) -> Pendiente | L6: Ej. 08:20. | M6: Torre de Control → pestaña Monitores (guardar). Tabla TorreControlMonitores_RM. Alcance: global (BD).
A7: 2 | B7: Torre · Ventana | C7: Ventana: hasta | D7: Hora en que termina la vigilancia del día. | E7: hh:mm | F7: 0.66666667 | H7: 0.5 | I7: 0.83333333 | J7: Sugerido | K7: =IF(G7="","Pendiente",IF(AND(ISNUMBER(G7),G7>=H7,G7<=I7),"OK","Fuera de rango")) -> Pendiente | L7: Debe ser posterior al «desde». Ej. 16:00. | M7: Torre de Control → pestaña Monitores (guardar). Tabla TorreControlMonitores_RM. Alcance: global (BD).
A8: 3 | B8: Torre · Mute tras contacto | C8: Mute tras contacto | D8: Minutos de silencio de una alerta después de registrar un contacto. También lo usan Supervisión Virtual y Cobros del día. | E8: minutos | F8: 60 | H8: 5 | I8: 240 | J8: Sugerido | K8: =IF(G8="","Pendiente",IF(AND(ISNUMBER(G8),G8>=H8,G8<=I8),"OK","Fuera de rango")) -> Pendiente | L8: El sistema exige al menos 1 minuto. Ej. 60. | M8: Torre de Control → pestaña Monitores (guardar). Tabla TorreControlMonitores_RM. Alcance: global (BD).
A9: 4 | B9: Torre · Representantes sin alerta | C9: Representantes sin alerta (lista) | D9: Vendedores que no generan alertas (códigos). | E9: texto | F9: vacío | H9: Texto | I9: Texto | J9: Texto | K9: =IF(G9="","Pendiente","OK") -> Pendiente | L9: Escriba los códigos de vendedor separados por coma (ej. 12,45,89). | M9: Torre de Control → pestaña Monitores (guardar). Tabla TorreControlMonitores_RM. Alcance: global (BD).
A10: Monitores de alerta: umbral, severidad (1 = baja … 3 = alta) y si están activos
A11: 5 | B11: Torre · PRIMERA_VISITA_PEDIDO | C11: PRIMERA_VISITA_PEDIDO: umbral | D11: Hora límite del primer pedido. Alarma si es más tarde. | E11: hh:mm | F11: 0.34722222 | H11: 0.29166667 | I11: 0.41666667 | J11: Sugerido | K11: =IF(G11="","Pendiente",IF(AND(ISNUMBER(G11),G11>=H11,G11<=I11),"OK","Fuera de rango")) -> Pendiente | L11: Ej. 08:20. (Internamente 500 minutos.) | M11: Torre de Control → pestaña Monitores (guardar). Tabla TorreControlMonitores_RM. Alcance: global (BD).
A12: 6 | B12: Torre · PRIMERA_VISITA_PEDIDO | C12: PRIMERA_VISITA_PEDIDO: severidad | D12: Importancia de la alerta en el orden de pantalla. | E12: 1 a 3 | F12: 3 | H12: 1 | I12: 3 | J12: Sugerido | K12: =IF(G12="","Pendiente",IF(AND(ISNUMBER(G12),G12>=H12,G12<=I12),"OK","Fuera de rango")) -> Pendiente | L12: 1 = baja, 2 = media, 3 = alta. | M12: Torre de Control → pestaña Monitores (guardar). Tabla TorreControlMonitores_RM. Alcance: global (BD).
A13: 7 | B13: Torre · TIEMPO_VISITA | C13: TIEMPO_VISITA: mínimo | D13: Alarma si la visita promedio dura MENOS de estos minutos. | E13: minutos | F13: 3 | H13: 1 | I13: 10 | J13: Sugerido | K13: =IF(G13="","Pendiente",IF(AND(ISNUMBER(G13),G13>=H13,G13<=I13),"OK","Fuera de rango")) -> Pendiente | L13: Ej. 3. | M13: Torre de Control → pestaña Monitores (guardar). Tabla TorreControlMonitores_RM. Alcance: global (BD).
A14: 8 | B14: Torre · TIEMPO_VISITA | C14: TIEMPO_VISITA: máximo | D14: Alarma si la visita promedio dura MÁS de estos minutos. | E14: minutos | F14: 40 | H14: 20 | I14: 90 | J14: Sugerido | K14: =IF(G14="","Pendiente",IF(AND(ISNUMBER(G14),G14>=H14,G14<=I14),"OK","Fuera de rango")) -> Pendiente | L14: Debe ser mayor que el mínimo. Ej. 40. | M14: Torre de Control → pestaña Monitores (guardar). Tabla TorreControlMonitores_RM. Alcance: global (BD).
A15: 9 | B15: Torre · TIEMPO_VISITA | C15: TIEMPO_VISITA: severidad | D15: Importancia de la alerta. | E15: 1 a 3 | F15: 1 | H15: 1 | I15: 3 | J15: Sugerido | K15: =IF(G15="","Pendiente",IF(AND(ISNUMBER(G15),G15>=H15,G15<=I15),"OK","Fuera de rango")) -> Pendiente | L15: 1 = baja, 2 = media, 3 = alta. | M15: Torre de Control → pestaña Monitores (guardar). Tabla TorreControlMonitores_RM. Alcance: global (BD).
A16: 10 | B16: Torre · CUMPLIMIENTO | C16: CUMPLIMIENTO: umbral | D16: Alarma si (visitados ÷ esperados a esta hora) es menor a este porcentaje. | E16: % | F16: 85 | H16: 50 | I16: 100 | J16: Sugerido | K16: =IF(G16="","Pendiente",IF(AND(ISNUMBER(G16),G16>=H16,G16<=I16),"OK","Fuera de rango")) -> Pendiente | L16: Ej. 85. | M16: Torre de Control → pestaña Monitores (guardar). Tabla TorreControlMonitores_RM. Alcance: global (BD).
A17: 11 | B17: Torre · CUMPLIMIENTO | C17: CUMPLIMIENTO: severidad | D17: Importancia de la alerta. | E17: 1 a 3 | F17: 2 | H17: 1 | I17: 3 | J17: Sugerido | K17: =IF(G17="","Pendiente",IF(AND(ISNUMBER(G17),G17>=H17,G17<=I17),"OK","Fuera de rango")) -> Pendiente | L17: 1 = baja, 2 = media, 3 = alta. | M17: Torre de Control → pestaña Monitores (guardar). Tabla TorreControlMonitores_RM. Alcance: global (BD).
A18: 12 | B18: Torre · EFECTIVIDAD_VISITA | C18: EFECTIVIDAD_VISITA: umbral | D18: Alarma si (clientes con pedido ÷ visitados) es menor a este porcentaje. | E18: % | F18: 55 | H18: 30 | I18: 80 | J18: Sugerido | K18: =IF(G18="","Pendiente",IF(AND(ISNUMBER(G18),G18>=H18,G18<=I18),"OK","Fuera de rango")) -> Pendiente | L18: Ej. 55. | M18: Torre de Control → pestaña Monitores (guardar). Tabla TorreControlMonitores_RM. Alcance: global (BD).
A19: 13 | B19: Torre · EFECTIVIDAD_VISITA | C19: EFECTIVIDAD_VISITA: severidad | D19: Importancia de la alerta. | E19: 1 a 3 | F19: 2 | H19: 1 | I19: 3 | J19: Sugerido | K19: =IF(G19="","Pendiente",IF(AND(ISNUMBER(G19),G19>=H19,G19<=I19),"OK","Fuera de rango")) -> Pendiente | L19: 1 = baja, 2 = media, 3 = alta. | M19: Torre de Control → pestaña Monitores (guardar). Tabla TorreControlMonitores_RM. Alcance: global (BD).
A20: 14 | B20: Torre · MUCHO_SIN_SYNC | C20: MUCHO_SIN_SYNC: umbral | D20: Alarma si el vendedor lleva más de estos minutos sin sincronizar. | E20: minutos | F20: 45 | H20: 15 | I20: 180 | J20: Sugerido | K20: =IF(G20="","Pendiente",IF(AND(ISNUMBER(G20),G20>=H20,G20<=I20),"OK","Fuera de rango")) -> Pendiente | L20: Ej. 45. | M20: Torre de Control → pestaña Monitores (guardar). Tabla TorreControlMonitores_RM. Alcance: global (BD).
A21: 15 | B21: Torre · MUCHO_SIN_SYNC | C21: MUCHO_SIN_SYNC: severidad | D21: Importancia de la alerta. | E21: 1 a 3 | F21: 3 | H21: 1 | I21: 3 | J21: Sugerido | K21: =IF(G21="","Pendiente",IF(AND(ISNUMBER(G21),G21>=H21,G21<=I21),"OK","Fuera de rango")) -> Pendiente | L21: 1 = baja, 2 = media, 3 = alta. | M21: Torre de Control → pestaña Monitores (guardar). Tabla TorreControlMonitores_RM. Alcance: global (BD).
A22: 16 | B22: Torre · FUERA_ENTORNO | C22: FUERA_ENTORNO: umbral | D22: Alarma si el GPS está a más de estos kilómetros del cliente de su ruta más cercano. | E22: km | F22: 3 | H22: 0.5 | I22: 20 | J22: Sugerido | K22: =IF(G22="","Pendiente",IF(AND(ISNUMBER(G22),G22>=H22,G22<=I22),"OK","Fuera de rango")) -> Pendiente | L22: Ej. 3 (admite decimales, 0.5). | M22: Torre de Control → pestaña Monitores (guardar). Tabla TorreControlMonitores_RM. Alcance: global (BD).
... A28: 22 | B28: Torre · ULTIMO_PEDIDO_TEMPRANO | C28: ULTIMO_PEDIDO_TEMPRANO: severidad | D28: Importancia de la alerta. | E28: 1 a 3 | F28: 2 | H28: 1 | I28: 3 | J28: Sugerido | K28: =IF(G28="","Pendiente",IF(AND(ISNUMBER(G28),G28>=H28,G28<=I28),"OK","Fuera de rango")) -> Pendiente | L28: 1 = baja, 2 = media, 3 = alta. | M28: Torre de Control → pestaña Monitores (guardar). Tabla TorreControlMonitores_RM. Alcance: global (BD).
A29: 23 | B29: Torre · PRIMERA_VISITA_PEDIDO | C29: PRIMERA_VISITA_PEDIDO: activo | D29: Enciende o apaga este monitor. | E29: lista | F29: Sí | H29: Lista | I29: Sí / No | J29: Lista | K29: =IF(G29="","Pendiente","OK") -> Pendiente | L29: Elija Sí o No. | M29: Torre de Control → pestaña Monitores (guardar). Tabla TorreControlMonitores_RM. Alcance: global (BD).
A30: 24 | B30: Torre · TIEMPO_VISITA | C30: TIEMPO_VISITA: activo | D30: Enciende o apaga este monitor. | E30: lista | F30: Sí | H30: Lista | I30: Sí / No | J30: Lista | K30: =IF(G30="","Pendiente","OK") -> Pendiente | L30: Elija Sí o No. | M30: Torre de Control → pestaña Monitores (guardar). Tabla TorreControlMonitores_RM. Alcance: global (BD).
A31: 25 | B31: Torre · CUMPLIMIENTO | C31: CUMPLIMIENTO: activo | D31: Enciende o apaga este monitor. | E31: lista | F31: Sí | H31: Lista | I31: Sí / No | J31: Lista | K31: =IF(G31="","Pendiente","OK") -> Pendiente | L31: Elija Sí o No. | M31: Torre de Control → pestaña Monitores (guardar). Tabla TorreControlMonitores_RM. Alcance: global (BD).
A32: 26 | B32: Torre · EFECTIVIDAD_VISITA | C32: EFECTIVIDAD_VISITA: activo | D32: Enciende o apaga este monitor. | E32: lista | F32: Sí | H32: Lista | I32: Sí / No | J32: Lista | K32: =IF(G32="","Pendiente","OK") -> Pendiente | L32: Elija Sí o No. | M32: Torre de Control → pestaña Monitores (guardar). Tabla TorreControlMonitores_RM. Alcance: global (BD).
A33: 27 | B33: Torre · MUCHO_SIN_SYNC | C33: MUCHO_SIN_SYNC: activo | D33: Enciende o apaga este monitor. | E33: lista | F33: Sí | H33: Lista | I33: Sí / No | J33: Lista | K33: =IF(G33="","Pendiente","OK") -> Pendiente | L33: Elija Sí o No. | M33: Torre de Control → pestaña Monitores (guardar). Tabla TorreControlMonitores_RM. Alcance: global (BD).
A34: 28 | B34: Torre · FUERA_ENTORNO | C34: FUERA_ENTORNO: activo | D34: Enciende o apaga este monitor. | E34: lista | F34: Sí | H34: Lista | I34: Sí / No | J34: Lista | K34: =IF(G34="","Pendiente","OK") -> Pendiente | L34: Elija Sí o No. | M34: Torre de Control → pestaña Monitores (guardar). Tabla TorreControlMonitores_RM. Alcance: global (BD).
A35: 29 | B35: Torre · PEDIDO_FUERA_DIA | C35: PEDIDO_FUERA_DIA: activo | D35: Enciende o apaga este monitor. | E35: lista | F35: Sí | H35: Lista | I35: Sí / No | J35: Lista | K35: =IF(G35="","Pendiente","OK") -> Pendiente | L35: Elija Sí o No. | M35: Torre de Control → pestaña Monitores (guardar). Tabla TorreControlMonitores_RM. Alcance: global (BD).
A36: 30 | B36: Torre · CUADRE_CERRADO | C36: CUADRE_CERRADO: activo | D36: Enciende o apaga este monitor. | E36: lista | F36: Sí | H36: Lista | I36: Sí / No | J36: Lista | K36: =IF(G36="","Pendiente","OK") -> Pendiente | L36: Elija Sí o No. | M36: Torre de Control → pestaña Monitores (guardar). Tabla TorreControlMonitores_RM. Alcance: global (BD).
A37: 31 | B37: Torre · ULTIMO_PEDIDO_TEMPRANO | C37: ULTIMO_PEDIDO_TEMPRANO: activo | D37: Enciende o apaga este monitor. | E37: lista | F37: Sí | H37: Lista | I37: Sí / No | J37: Lista | K37: =IF(G37="","Pendiente","OK") -> Pendiente | L37: Elija Sí o No. | M37: Torre de Control → pestaña Monitores (guardar). Tabla TorreControlMonitores_RM. Alcance: global (BD).
A38: Monitores personalizados (plantilla: copie la fila por cada monitor nuevo que desee)
A39: 32 | B39: Torre · Personalizado | C39: Objetivo por día | D39: Meta que debe cumplir cada vendedor por día. | E39: número | F39: 5 | H39: 0 | I39: 1000 | J39: Sugerido | K39: =IF(G39="","Pendiente",IF(AND(ISNUMBER(G39),G39>=H39,G39<=I39),"OK","Fuera de rango")) -> Pendiente | L39: Ej. 5 clientes activados por día. | M39: Torre de Control → Monitores personalizados. Alcance: global (BD).
A40: 33 | B40: Torre · Personalizado | C40: Comparador | D40: Cómo se compara el avance contra el objetivo. | E40: lista | F40: mayorIgual | H40: Lista | I40: mayorIgual / menor / ritmo | J40: Lista | K40: =IF(G40="","Pendiente","OK") -> Pendiente | L40: «mayorIgual» = debe llegar o superar; «menor» = debe ser menor; «ritmo» = avance proporcional entre dos horas. | M40: Torre de Control → Monitores personalizados.
A41: 34 | B41: Torre · Personalizado | C41: Métrica | D41: Qué se cuenta. | E41: lista | F41: clientes | H41: Lista | I41: clientes / unidades / monto / impactos | J41: Lista | K41: =IF(G41="","Pendiente","OK") -> Pendiente | L41: Elija la métrica. | M41: Torre de Control → Monitores personalizados.
A42: 35 | B42: Torre · Personalizado | C42: Unidades mínimas por cliente | D42: Unidades que debe comprar un cliente para contarse como activado. | E42: unidades | F42: 1 | H42: 0 | I42: 100 | J42: Sugerido | K42: =IF(G42="","Pendiente",IF(AND(ISNUMBER(G42),G42>=H42,G42<=I42),"OK","Fuera de rango")) -> Pendiente | L42: Ej. 1. | M42: Torre de Control → Monitores personalizados.
A43: 36 | B43: Torre · Personalizado | C43: Contar solo hasta la hora (opcional) | D43: Solo cuenta ventas hechas antes de esta hora. | E43: hh:mm | F43: 0.34722222 | H43: 0.25 | I43: 0.83333333 | J43: Sugerido | K43: =IF(G43="","Pendiente",IF(AND(ISNUMBER(G43),G43>=H43,G43<=I43),"OK","Fuera de rango")) -> Pendiente | L43: Opcional. Ej. 11:00. | M43: Torre de Control → Monitores personalizados.
A44: 37 | B44: Torre · Personalizado | C44: Ritmo: hora de inicio | D44: Desde cuándo se exige el avance (solo comparador «ritmo»). | E44: hh:mm | F44: 0.34722222 | H44: 0.25 | I44: 0.58333333 | J44: Sugerido | K44: =IF(G44="","Pendiente",IF(AND(ISNUMBER(G44),G44>=H44,G44<=I44),"OK","Fuera de rango")) -> Pendiente | L44: Ej. 08:20. Se fija en el sistema. | M44: Torre de Control → Monitores personalizados (código TorrePersonalizados).
A45: 38 | B45: Torre · Personalizado | C45: Ritmo: hora límite | D45: Hora en que ya debe llevar el 100 % del objetivo. | E45: hh:mm | F45: 0.625 | H45: 0.41666667 | I45: 0.83333333 | J45: Sugerido | K45: =IF(G45="","Pendiente",IF(AND(ISNUMBER(G45),G45>=H45,G45<=I45),"OK","Fuera de rango")) -> Pendiente | L45: Ej. 15:00. Posterior a la hora de inicio. | M45: Torre de Control → Monitores personalizados (código TorrePersonalizados).
A46: 39 | B46: Torre · Personalizado | C46: Severidad | D46: Importancia de la alerta. | E46: 1 a 3 | F46: 2 | H46: 1 | I46: 3 | J46: Validado | K46: =IF(G46="","Pendiente",IF(AND(ISNUMBER(G46),G46>=H46,G46<=I46),"OK","Fuera de rango")) -> Pendiente | L46: 1 = baja, 2 = media, 3 = alta. | M46: Torre de Control → Monitores personalizados.
...

Sheet 3 Geolocalizaciones
A1: 3 · Geolocalizaciones (mapa)
A2: Cuándo el punto de un vendedor se pinta verde / amarillo / rojo en el mapa, por sincronización y por cercanía a la ruta.
A3: Se guarda en cada navegador; configure igual en cada computadora que use el mapa.
A5: # | B5: Pantalla / apartado | C5: Parámetro | D5: Qué controla | E5: Unidad | F5: Valor actual (por defecto) | G5: VALOR A CONFIGURAR (llenar) | H5: Rango DESDE | I5: Rango HASTA | J5: Tipo de rango | K5: Estado | L5: Cómo llenarlo / ejemplo | M5: Dónde se configura (y alcance)
A6: Tiempo sin sincronizar
A7: 1 | B7: Geo · Ubicación de vendedores | C7: Sync verde: hasta | D7: Minutos sin sincronizar para considerarse «al día» (verde). | E7: minutos | F7: 30 | H7: 1 | I7: 240 | J7: Sugerido | K7: =IF(G7="","Pendiente",IF(AND(ISNUMBER(G7),G7>=H7,G7<=I7),"OK","Fuera de rango")) -> Pendiente | L7: Menos de este tiempo = verde. | M7: Geolocalizaciones → ⚙ (engranaje). Alcance: por usuario/navegador (cada PC).
A8: 2 | B8: Geo · Ubicación de vendedores | C8: Sync amarillo: hasta | D8: Minutos máximos para estar en amarillo (más que eso = rojo). | E8: minutos | F8: 45 | H8: 1 | I8: 480 | J8: Sugerido | K8: =IF(G8="","Pendiente",IF(AND(ISNUMBER(G8),G8>=H8,G8<=I8),"OK","Fuera de rango")) -> Pendiente | L8: Debe ser MAYOR o igual que el verde. | M8: Geolocalizaciones → ⚙ (engranaje). Alcance: por usuario/navegador (cada PC).
A9: 3 | B9: Geo · Ubicación de vendedores | C9: Ventana de ubicaciones | D9: Antigüedad máxima de la última ubicación mostrada. | E9: horas | F9: 48 | H9: 1 | I9: 720 | J9: Validado | K9: =IF(G9="","Pendiente",IF(AND(ISNUMBER(G9),G9>=H9,G9<=I9),"OK","Fuera de rango")) -> Pendiente | L9: El sistema acepta de 1 a 720 horas. | M9: Geolocalizaciones → campo «Ventana (h)». Alcance: por consulta.
A10: Cercanía a la ruta
A11: 4 | B11: Geo · Ubicación de la ruta | C11: Ruta verde: hasta | D11: Metros al cliente de ruta más cercano para estar «en ruta» (verde). | E11: metros | F11: 400 | H11: 1 | I11: 5000 | J11: Sugerido | K11: =IF(G11="","Pendiente",IF(AND(ISNUMBER(G11),G11>=H11,G11<=I11),"OK","Fuera de rango")) -> Pendiente | L11: Ej. 400. | M11: Geolocalizaciones → ⚙ (engranaje). Alcance: por usuario/navegador (cada PC).
A12: 5 | B12: Geo · Ubicación de la ruta | C12: Ruta amarillo: hasta | D12: Metros máximos para «alejado» (más allá = fuera de ruta, rojo). | E12: metros | F12: 1000 | H12: 1 | I12: 10000 | J12: Sugerido | K12: =IF(G12="","Pendiente",IF(AND(ISNUMBER(G12),G12>=H12,G12<=I12),"OK","Fuera de rango")) -> Pendiente | L12: Debe ser MAYOR o igual que el verde. | M12: Geolocalizaciones → ⚙ (engranaje). Alcance: por usuario/navegador (cada PC).

Sheet 4 Home-Visitas
A1: 4 · Home / Visitas (tablero del día)
A2: Horas límite para considerar «a tiempo» la primera visita y el primer pedido; de ellas dependen los colores y los porcentajes «a tiempo» del tablero.
A3: Se guarda en cada navegador. El conteo de «tardíos» al imprimir usa 08:20 fijo.
A5: # | B5: Pantalla / apartado | C5: Parámetro | D5: Qué controla | E5: Unidad | F5: Valor actual (por defecto) | G5: VALOR A CONFIGURAR (llenar) | H5: Rango DESDE | I5: Rango HASTA | J5: Tipo de rango | K5: Estado | L5: Cómo llenarlo / ejemplo | M5: Dónde se configura (y alcance)
A6: 1 | B6: Home · Visitas | C6: Primera visita a tiempo: hasta | D6: Hora límite de la primera entrada del día para estar «a tiempo». | E6: hh:mm | F6: 0.33333333 | H6: 0.25 | I6: 0.5 | J6: Sugerido | K6: =IF(G6="","Pendiente",IF(AND(ISNUMBER(G6),G6>=H6,G6<=I6),"OK","Fuera de rango")) -> Pendiente | L6: Ej. 08:00. | M6: Home (Visitas) → panel ⚙ de umbrales. Alcance: por usuario/navegador (cada PC).
A7: 2 | B7: Home · Visitas | C7: Primer pedido a tiempo: hasta | D7: Hora límite del primer pedido del día para estar «a tiempo». | E7: hh:mm | F7: 0.34722222 | H7: 0.25 | I7: 0.5 | J7: Sugerido | K7: =IF(G7="","Pendiente",IF(AND(ISNUMBER(G7),G7>=H7,G7<=I7),"OK","Fuera de rango")) -> Pendiente | L7: Ej. 08:20. | M7: Home (Visitas) → panel ⚙ de umbrales. Alcance: por usuario/navegador (cada PC).

Sheet 5 Supervisión
A1: 5 · Supervisión Dinámica
A2: Pesos del Índice Global, factores de acompañamiento/auditoría, semáforo y metas de Cobros del día, y cronograma semanal.
A3: Las bandas de calidad de Supervisión (85/70/55) están fijas en código: véalas en la hoja «8 Fijos en código».
A5: # | B5: Pantalla / apartado | C5: Parámetro | D5: Qué controla | E5: Unidad | F5: Valor actual (por defecto) | G5: VALOR A CONFIGURAR (llenar) | H5: Rango DESDE | I5: Rango HASTA | J5: Tipo de rango | K5: Estado | L5: Cómo llenarlo / ejemplo | M5: Dónde se configura (y alcance)
A6: A. Pesos de los esquemas del Índice Global (deben sumar 100)
A7: 1 | B7: Supervisión | C7: Peso · Supervisión Virtual (IEGT) | D7: Cuánto aporta al Índice Global de Supervisión. | E7: % | F7: 50 | H7: 0 | I7: 100 | J7: Validado | K7: =IF(G7="","Pendiente",IF(AND(ISNUMBER(G7),G7>=H7,G7<=I7),"OK","Fuera de rango")) -> Pendiente | L7: Entre 0 y 100. | M7: Supervisión → Configuración → Pesos. Solo Gerencia. Alcance: global (BD).
A8: 2 | B8: Supervisión | C8: Peso · Calle — Acompañamiento | D8: Cuánto aporta la supervisión de acompañamiento en calle. | E8: % | F8: 35 | H8: 0 | I8: 100 | J8: Validado | K8: =IF(G8="","Pendiente",IF(AND(ISNUMBER(G8),G8>=H8,G8<=I8),"OK","Fuera de rango")) -> Pendiente | L8: Entre 0 y 100. | M8: Supervisión → Configuración → Pesos. Solo Gerencia. Alcance: global (BD).
A9: 3 | B9: Supervisión | C9: Peso · Calle — Auditoría | D9: Cuánto aporta la auditoría en calle. | E9: % | F9: 15 | H9: 0 | I9: 100 | J9: Validado | K9: =IF(G9="","Pendiente",IF(AND(ISNUMBER(G9),G9>=H9,G9<=I9),"OK","Fuera de rango")) -> Pendiente | L9: Entre 0 y 100. | M9: Supervisión → Configuración → Pesos. Solo Gerencia. Alcance: global (BD).
C10: Suma de pesos de esquemas (debe ser 100) | D10: Se calcula sola. | E10: % | F10: 100 | G10: =SUM(G7:G9) -> 0 | H10: 100 | I10: 100 | J10: Calculado | K10: =IF(COUNT(G7:G9)=0,"Pendiente",IF(ROUND(G10,4)=100,"OK","Fuera de rango")) -> Pendiente | L10: No se llena: se calcula solo.
A11: B. Factores de Acompañamiento (deben sumar 100)
A12: 4 | B12: Supervisión | C12: Factor · Preparación | D12: Peso de este factor en la nota de acompañamiento. | E12: % | F12: 12 | H12: 0 | I12: 100 | J12: Validado | K12: =IF(G12="","Pendiente",IF(AND(ISNUMBER(G12),G12>=H12,G12<=I12),"OK","Fuera de rango")) -> Pendiente | L12: Entre 0 y 100. | M12: Supervisión → Configuración → Pesos. Solo Gerencia. Alcance: global (BD).
A13: 5 | B13: Supervisión | C13: Factor · Saludo | D13: Peso de este factor en la nota de acompañamiento. | E13: % | F13: 15 | H13: 0 | I13: 100 | J13: Validado | K13: =IF(G13="","Pendiente",IF(AND(ISNUMBER(G13),G13>=H13,G13<=I13),"OK","Fuera de rango")) -> Pendiente | L13: Entre 0 y 100. | M13: Supervisión → Configuración → Pesos. Solo Gerencia. Alcance: global (BD).
A14: 6 | B14: Supervisión | C14: Factor · Inventario | D14: Peso de este factor en la nota de acompañamiento. | E14: % | F14: 8 | H14: 0 | I14: 100 | J14: Validado | K14: =IF(G14="","Pendiente",IF(AND(ISNUMBER(G14),G14>=H14,G14<=I14),"OK","Fuera de rango")) -> Pendiente | L14: Entre 0 y 100. | M14: Supervisión → Configuración → Pesos. Solo Gerencia. Alcance: global (BD).
A15: 7 | B15: Supervisión | C15: Factor · Afiches | D15: Peso de este factor en la nota de acompañamiento. | E15: % | F15: 5 | H15: 0 | I15: 100 | J15: Validado | K15: =IF(G15="","Pendiente",IF(AND(ISNUMBER(G15),G15>=H15,G15<=I15),"OK","Fuera de rango")) -> Pendiente | L15: Entre 0 y 100. | M15: Supervisión → Configuración → Pesos. Solo Gerencia. Alcance: global (BD).
A16: 8 | B16: Supervisión | C16: Factor · Foto de éxito | D16: Peso de este factor en la nota de acompañamiento. | E16: % | F16: 5 | H16: 0 | I16: 100 | J16: Validado | K16: =IF(G16="","Pendiente",IF(AND(ISNUMBER(G16),G16>=H16,G16<=I16),"OK","Fuera de rango")) -> Pendiente | L16: Entre 0 y 100. | M16: Supervisión → Configuración → Pesos. Solo Gerencia. Alcance: global (BD).
A17: 9 | B17: Supervisión | C17: Factor · Presentación | D17: Peso de este factor en la nota de acompañamiento. | E17: % | F17: 22 | H17: 0 | I17: 100 | J17: Validado | K17: =IF(G17="","Pendiente",IF(AND(ISNUMBER(G17),G17>=H17,G17<=I17),"OK","Fuera de rango")) -> Pendiente | L17: Entre 0 y 100. | M17: Supervisión → Configuración → Pesos. Solo Gerencia. Alcance: global (BD).
A18: 10 | B18: Supervisión | C18: Factor · Cierre | D18: Peso de este factor en la nota de acompañamiento. | E18: % | F18: 20 | H18: 0 | I18: 100 | J18: Validado | K18: =IF(G18="","Pendiente",IF(AND(ISNUMBER(G18),G18>=H18,G18<=I18),"OK","Fuera de rango")) -> Pendiente | L18: Entre 0 y 100. | M18: Supervisión → Configuración → Pesos. Solo Gerencia. Alcance: global (BD).
A19: 11 | B19: Supervisión | C19: Factor · Herramienta | D19: Peso de este factor en la nota de acompañamiento. | E19: % | F19: 8 | H19: 0 | I19: 100 | J19: Validado | K19: =IF(G19="","Pendiente",IF(AND(ISNUMBER(G19),G19>=H19,G19<=I19),"OK","Fuera de rango")) -> Pendiente | L19: Entre 0 y 100. | M19: Supervisión → Configuración → Pesos. Solo Gerencia. Alcance: global (BD).
A20: 12 | B20: Supervisión | C20: Factor · Datos del cliente | D20: Peso de este factor en la nota de acompañamiento. | E20: % | F20: 5 | H20: 0 | I20: 100 | J20: Validado | K20: =IF(G20="","Pendiente",IF(AND(ISNUMBER(G20),G20>=H20,G20<=I20),"OK","Fuera de rango")) -> Pendiente | L20: Entre 0 y 100. | M20: Supervisión → Configuración → Pesos. Solo Gerencia. Alcance: global (BD).
C21: Suma de factores de Acompañamiento (debe ser 100) | D21: Se calcula sola. | E21: % | F21: 100 | G21: =SUM(G12:G20) -> 0 | H21: 100 | I21: 100 | J21: Calculado | K21: =IF(COUNT(G12:G20)=0,"Pendiente",IF(ROUND(G21,4)=100,"OK","Fuera de rango")) -> Pendiente | L21: No se llena: se calcula solo.
A22: C. Factores de Auditoría (deben sumar 100)
A23: 13 | B23: Supervisión | C23: Factor · Conoce al vendedor | D23: Peso de este factor en la nota de auditoría. | E23: % | F23: 10 | H23: 0 | I23: 100 | J23: Validado | K23: =IF(G23="","Pendiente",IF(AND(ISNUMBER(G23),G23>=H23,G23<=I23),"OK","Fuera de rango")) -> Pendiente | L23: Entre 0 y 100. | M23: Supervisión → Configuración → Pesos. Solo Gerencia. Alcance: global (BD).
A24: 14 | B24: Supervisión | C24: Factor · Puntos al vendedor | D24: Peso de este factor en la nota de auditoría. | E24: % | F24: 20 | H24: 0 | I24: 100 | J24: Validado | K24: =IF(G24="","Pendiente",IF(AND(ISNUMBER(G24),G24>=H24,G24<=I24),"OK","Fuera de rango")) -> Pendiente | L24: Entre 0 y 100. | M24: Supervisión → Configuración → Pesos. Solo Gerencia. Alcance: global (BD).
A25: 15 | B25: Supervisión | C25: Factor · Entregas | D25: Peso de este factor en la nota de auditoría. | E25: % | F25: 15 | H25: 0 | I25: 100 | J25: Validado | K25: =IF(G25="","Pendiente",IF(AND(ISNUMBER(G25),G25>=H25,G25<=I25),"OK","Fuera de rango")) -> Pendiente | L25: Entre 0 y 100. | M25: Supervisión → Configuración → Pesos. Solo Gerencia. Alcance: global (BD).
A26: 16 | B26: Supervisión | C26: Factor · Maneja productos | D26: Peso de este factor en la nota de auditoría. | E26: % | F26: 20 | H26: 0 | I26: 100 | J26: Validado | K26: =IF(G26="","Pendiente",IF(AND(ISNUMBER(G26),G26>=H26,G26<=I26),"OK","Fuera de rango")) -> Pendiente | L26: Entre 0 y 100. | M26: Supervisión → Configuración → Pesos. Solo Gerencia. Alcance: global (BD).
A27: 17 | B27: Supervisión | C27: Factor · Precios | D27: Peso de este factor en la nota de auditoría. | E27: % | F27: 15 | H27: 0 | I27: 100 | J27: Validado | K27: =IF(G27="","Pendiente",IF(AND(ISNUMBER(G27),G27>=H27,G27<=I27),"OK","Fuera de rango")) -> Pendiente | L27: Entre 0 y 100. | M27: Supervisión → Configuración → Pesos. Solo Gerencia. Alcance: global (BD).
A28: 18 | B28: Supervisión | C28: Factor · POP | D28: Peso de este factor en la nota de auditoría. | E28: % | F28: 10 | H28: 0 | I28: 100 | J28: Validado | K28: =IF(G28="","Pendiente",IF(AND(ISNUMBER(G28),G28>=H28,G28<=I28),"OK","Fuera de rango")) -> Pendiente | L28: Entre 0 y 100. | M28: Supervisión → Configuración → Pesos. Solo Gerencia. Alcance: global (BD).
A29: 19 | B29: Supervisión | C29: Factor · Exhibidor | D29: Peso de este factor en la nota de auditoría. | E29: % | F29: 10 | H29: 0 | I29: 100 | J29: Validado | K29: =IF(G29="","Pendiente",IF(AND(ISNUMBER(G29),G29>=H29,G29<=I29),"OK","Fuera de rango")) -> Pendiente | L29: Entre 0 y 100. | M29: Supervisión → Configuración → Pesos. Solo Gerencia. Alcance: global (BD).
C30: Suma de factores de Auditoría (debe ser 100) | D30: Se calcula sola. | E30: % | F30: 100 | G30: =SUM(G23:G29) -> 0 | H30: 100 | I30: 100 | J30: Calculado | K30: =IF(COUNT(G23:G29)=0,"Pendiente",IF(ROUND(G30,4)=100,"OK","Fuera de rango")) -> Pendiente | L30: No se llena: se calcula solo.
A31: D. Texto de la marca del índice
A32: 20 | B32: Supervisión | C32: Nombre del índice (apodo) | D32: Texto que reemplaza «IEGT» en pantallas y reportes (ej. AMCO-GT). | E32: texto | F32: AMCO-GT | H32: Texto | I32: Texto | J32: Texto | K32: =IF(G32="","Pendiente","OK") -> Pendiente | L32: Máximo 60 caracteres. | M32: Supervisión → Configuración → Pesos. Tabla ConfiguracionApp_RM, clave IegtApodo. Alcance: global (BD).
A33: E. Cobros del día — semáforo y metas de cada alerta (repita las filas por cada alerta)
A34: 21 | B34: Cobros del día | C34: Umbral verde (≥) | D34: % de logro (real o proyectado) desde el cual el semáforo es verde. | E34: % | F34: 90 | H34: 50 | I34: 150 | J34: Sugerido | K34: =IF(G34="","Pendiente",IF(AND(ISNUMBER(G34),G34>=H34,G34<=I34),"OK","Fuera de rango")) -> Pendiente | L34: Ej. 90. No use 0. | M34: Supervisión → Cobros del día → mantenimiento de alertas. Solo Gerencia. Alcance: global (BD).
A35: 22 | B35: Cobros del día | C35: Umbral amarillo (≥) | D35: % de logro desde el cual es amarillo (por debajo, rojo). | E35: % | F35: 80 | H35: 50 | I35: 150 | J35: Sugerido | K35: =IF(G35="","Pendiente",IF(AND(ISNUMBER(G35),G35>=H35,G35<=I35),"OK","Fuera de rango")) -> Pendiente | L35: Debe ser MENOR que el verde. No use 0. | M35: Supervisión → Cobros del día → mantenimiento de alertas. Solo Gerencia. Alcance: global (BD).
A36: 23 | B36: Cobros del día | C36: Meta fija por vendedor y día · Pedidos | D36: Cantidad de pedidos diarios que debe hacer cada vendedor. | E36: pedidos | F36: 42 | H36: 0 | I36: 1000 | J36: Sugerido | K36: =IF(G36="","Pendiente",IF(AND(ISNUMBER(G36),G36>=H36,G36<=I36),"OK","Fuera de rango")) -> Pendiente | L36: Solo para alertas de tipo «pedidos». | M36: Supervisión → Cobros del día → mantenimiento de alertas. Solo Gerencia. Alcance: global (BD).
A37: 24 | B37: Cobros del día | C37: Meta fija por vendedor y día · Producto | D37: Unidades diarias de un producto por vendedor. | E37: unidades | F37: 10 | H37: 0 | I37: 1000 | J37: Sugerido | K37: =IF(G37="","Pendiente",IF(AND(ISNUMBER(G37),G37>=H37,G37<=I37),"OK","Fuera de rango")) -> Pendiente | L37: Solo para alertas de tipo «producto». | M37: Supervisión → Cobros del día → mantenimiento de alertas. Solo Gerencia. Alcance: global (BD).
A38: 25 | B38: Cobros del día | C38: Supervisores excluidos | D38: Supervisores a los que NO aplica la alerta (códigos). | E38: texto | F38: S12,S13 | H38: Texto | I38: Texto | J38: Texto | K38: =IF(G38="","Pendiente","OK") -> Pendiente | L38: Códigos separados por coma. Déjelo vacío si no excluye a nadie. | M38: Supervisión → Cobros del día → mantenimiento de alertas. Solo Gerencia. Alcance: global (BD).
A39: F. Cronograma semanal de supervisión (tipo de supervisión por día)
A40: 26 | B40: Supervisión · Cronograma | C40: Tipo de supervisión · Lunes | D40: Qué tipo de supervisión se hace ese día (patrón del equipo). | E40: lista | F40: Virtual | H40: Lista | I40: Virtual / Presencial / Auditoría | J40: Lista | K40: =IF(G40="","Pendiente","OK") -> Pendiente | L40: Elija el tipo. Cada vendedor puede tener una excepción. | M40: Supervisión → ⚙ Configurar cronograma. Alcance: global (BD).
A41: 27 | B41: Supervisión · Cronograma | C41: Tipo de supervisión · Martes | D41: Qué tipo de supervisión se hace ese día (patrón del equipo). | E41: lista | F41: Presencial | H41: Lista | I41: Virtual / Presencial / Auditoría | J41: Lista | K41: =IF(G41="","Pendiente","OK") -> Pendiente | L41: Elija el tipo. Cada vendedor puede tener una excepción. | M41: Supervisión → ⚙ Configurar cronograma. Alcance: global (BD).
...

Sheet 6 Presupuesto-Gestión
A1: 6 · Gestión de presupuesto (motor «Generar»)
A2: Variables que ajustan el presupuesto propuesto. Cada valor puede ser Global, por Suplidor, por Categoría o por Ruta-Suplidor, con vigencia por Año, Trimestre o Mes (gana el más específico).
A3: Anote cada valor con su ámbito y vigencia en «Cómo llenarlo» (ej. «Suplidor 101, sep–dic 2026»). Copie la fila si hay varios valores.
A5: # | B5: Pantalla / apartado | C5: Parámetro | D5: Qué controla | E5: Unidad | F5: Valor actual (por defecto) | G5: VALOR A CONFIGURAR (llenar) | H5: Rango DESDE | I5: Rango HASTA | J5: Tipo de rango | K5: Estado | L5: Cómo llenarlo / ejemplo | M5: Dónde se configura (y alcance)
A6: A. Variables ajustables
A7: 1 | B7: Presupuesto · Variables | C7: Factor de crecimiento mensual | D7: Multiplicador sobre la base histórica neta (1.02 = +2 %). | E7: factor | F7: 1 | H7: 0.5 | I7: 2 | J7: Sugerido | K7: =IF(G7="","Pendiente",IF(AND(ISNUMBER(G7),G7>=H7,G7<=I7),"OK","Fuera de rango")) -> Pendiente | L7: 1.00 = igual a la base. Indique suplidor y meses. Ej. 1.020 para +2 %. | M7: Gestión de presupuesto → Configuración de variables. Solo Gerencia. Alcance: global (BD).
A8: 2 | B8: Presupuesto · Variables | C8: Meta Rappel mensual (por suplidor) | D8: Meta mensual fija por suplidor; actúa como piso. | E8: RD$/mes | F8: sin meta | H8: 0 | I8: 1000000000 | J8: Sugerido | K8: =IF(G8="","Pendiente",IF(AND(ISNUMBER(G8),G8>=H8,G8<=I8),"OK","Fuera de rango")) -> Pendiente | L8: Indique suplidor y vigencia. Ej. 22,800,000. | M8: Gestión de presupuesto → Configuración de variables. Solo Gerencia. Alcance: global (BD).
A9: 3 | B9: Presupuesto · Variables | C9: Piso mínimo (% de la base) | D9: Nunca proponer menos de este porcentaje de la base. | E9: % | F9: 0 | H9: 0 | I9: 150 | J9: Sugerido | K9: =IF(G9="","Pendiente",IF(AND(ISNUMBER(G9),G9>=H9,G9<=I9),"OK","Fuera de rango")) -> Pendiente | L9: 0 = sin piso. Ej. 90. | M9: Gestión de presupuesto → Configuración de variables. Solo Gerencia. Alcance: global (BD).
A10: 4 | B10: Presupuesto · Variables | C10: Factor ruta-proveedor | D10: Ajuste fino por vendedor × suplidor. | E10: factor | F10: 1 | H10: 0.5 | I10: 2 | J10: Sugerido | K10: =IF(G10="","Pendiente",IF(AND(ISNUMBER(G10),G10>=H10,G10<=I10),"OK","Fuera de rango")) -> Pendiente | L10: 1.00 = sin ajuste. | M10: Gestión de presupuesto → Configuración de variables. Solo Gerencia. Alcance: global (BD).
A11: 5 | B11: Presupuesto · Variables | C11: Umbral de anomalía | D11: Marca como «anomalía» (sin bloquear) si lo propuesto se desvía más de este % de la base. | E11: % | F11: 50 | H11: 10 | I11: 200 | J11: Sugerido | K11: =IF(G11="","Pendiente",IF(AND(ISNUMBER(G11),G11>=H11,G11<=I11),"OK","Fuera de rango")) -> Pendiente | L11: Ej. 50. | M11: Gestión de presupuesto → Configuración de variables. Solo Gerencia. Alcance: global (BD).
A12: 6 | B12: Presupuesto · Variables | C12: Umbral mínimo (monto) | D12: Monto total mínimo propuesto de un suplidor o categoría. | E12: RD$ | F12: sin umbral | H12: 0 | I12: 1000000000 | J12: Sugerido | K12: =IF(G12="","Pendiente",IF(AND(ISNUMBER(G12),G12>=H12,G12<=I12),"OK","Fuera de rango")) -> Pendiente | L12: Déjelo vacío si no aplica. | M12: Gestión de presupuesto → Configuración de variables. Solo Gerencia. Alcance: global (BD).
A13: 7 | B13: Presupuesto · Variables | C13: Umbral máximo (monto) | D13: Monto total máximo propuesto de un suplidor o categoría. | E13: RD$ | F13: sin umbral | H13: 0 | I13: 1000000000 | J13: Sugerido | K13: =IF(G13="","Pendiente",IF(AND(ISNUMBER(G13),G13>=H13,G13<=I13),"OK","Fuera de rango")) -> Pendiente | L13: Debe ser mayor que el mínimo. | M13: Gestión de presupuesto → Configuración de variables. Solo Gerencia. Alcance: global (BD).
A14: 8 | B14: Presupuesto · Variables | C14: Tope por activación obligatoria | D14: Máximo % del presupuesto total del lote que puede venir del incremento por Activación Obligatoria. | E14: % | F14: 5 | H14: 0 | I14: 20 | J14: Sugerido | K14: =IF(G14="","Pendiente",IF(AND(ISNUMBER(G14),G14>=H14,G14<=I14),"OK","Fuera de rango")) -> Pendiente | L14: Ej. 5. | M14: Gestión de presupuesto → Configuración de variables. Solo Gerencia. Alcance: global (BD).
A15: B. Otras metas del motor
A16: 9 | B16: Presupuesto · Efectividad | C16: Meta de efectividad — División 10 | D16: Meta de efectividad (clientes con pedido ÷ visitados) del motor para la división. | E16: % | F16: sin meta | H16: 0 | I16: 100 | J16: Sugerido | K16: =IF(G16="","Pendiente",IF(AND(ISNUMBER(G16),G16>=H16,G16<=I16),"OK","Fuera de rango")) -> Pendiente | L16: Déjelo vacío si no aplica. El sistema lo guarda como fracción (60 % = 0.60). | M16: Gestión de presupuesto → Metas de efectividad. Tabla PresupuestoEfectividadMetas_RM. Alcance: global (BD).
A17: 10 | B17: Presupuesto · Efectividad | C17: Meta de efectividad — División 11 | D17: Ídem para la división 11. | E17: % | F17: sin meta | H17: 0 | I17: 100 | J17: Sugerido | K17: =IF(G17="","Pendiente",IF(AND(ISNUMBER(G17),G17>=H17,G17<=I17),"OK","Fuera de rango")) -> Pendiente | L17: Ídem. | M17: Tabla PresupuestoEfectividadMetas_RM.
A18: 11 | B18: Presupuesto · Efectividad | C18: Meta de efectividad — División 12 | D18: Ídem para la división 12. | E18: % | F18: sin meta | H18: 0 | I18: 100 | J18: Sugerido | K18: =IF(G18="","Pendiente",IF(AND(ISNUMBER(G18),G18>=H18,G18<=I18),"OK","Fuera de rango")) -> Pendiente | L18: Ídem. | M18: Tabla PresupuestoEfectividadMetas_RM.
